Workbook

Sheet 12м
C1: Предварительная ведомость материалов | H1: Укажите тип обшивки
A3: Проектно-расчетный отдел | H3: наружная | I3: 2
H4: внутренняя | I4: 0
B5: Снег/Ветер : | C5: 3 | D5: 2 | F5: ТЗ № | G5: 22285 | O5: к/б
A6: место стр | B6: Коркино | H6: нет обшивки | J6: 0
A7: обьект | B7: Ангар | F7: =IF(I13=1,"альбом","проект") -> альбом | H7: оцинкованный профлист | J7: 1 | M7: шаг | N7: выс | O7: 2ур | P7: 3ур
B8: Пролет, м : | C8: 18 | F8: ур. отв | G8: 2 | H8: окрашенный профлист | J8: 2 | L8: 3сн | M8: 6 | N8: 6 | O8: (2,5/2,5) | P8: (2/2)
B9: Длина, м : | C9: 48 | F9: Ст.огн. | G9: 5 | H9: сайдинг (горизонт) | J9: 3 | N9: 3 | O9: (1,5/2,5) | P9: (1,5/2)
B10: Высота, м : | C10: 6 | H10: фасадная панель (верт.) | J10: 4 | L10: 4сн | M10: 5 | N10: 6 | O10: (2,5/2,5) | P10: (2/2)
A11: шаг рам, м : | C11: 4 | H11: ГВЛ | J11: 5 | N11: 3 | O11: (2/2,5) | P11: (1,5/2)
B12: наружная обшивка : | C12: СП | H12: Альбом-1 | I12: Выбрать 1или 2 | L12: 5сн | M12: 5 | N12: 6 | O12: (2,5/3) | P12: (2/2,5)
B13: внутренняя обшивка : | C13: нет | H13: Проект-2 | I13: 1 | J13: расчет балки | N13: 3 | O13: (2/3) | P13: (2/2,5)
D14: утепление кровли: | E14: 150 | F14: мм | J14: =15*3.14/180 -> 0.26166667 | M14: 2ур | N14: 3ур
D15: утепление стен: | E15: 100 | F15: мм | J15: =COS(J14) -> 0.96596017 | L15: 3сн | M15: =I36 -> ТПС 245х65х2 | N15: =I34 -> ТПС 200х65х2
I16: Кол.-во рам | J16: =C8/2/J15*2 -> 18.634309 | L16: шаг6
D17: перегородки | E17: =0 -> 0 | F17: м2 | I17: =CEILING(C9/C11+1,1) -> 13 | L17: 4сн | M17: =I34 -> ТПС 200х65х2 | N17: =I32 -> ТПС 200х2
A18: МАТЕРИАЛЫ ЗАО "ИНСИ" | I18: эл. Рамы | J18: цена п м | K18: вес пм | L18: шаг5
A19: № п.п. | B19: наименование | C19: кол-во | D19: ед. изм | E19: цена ед. | F19: цена | G19: общий вес, кг | H19: вес элемента,кг | I19: ПГС-S 300х80х1,5 | J19: =[1]Основные!$F$342 -> 1043.7 | K19: 5.974 | L19: 5сн | M19: =I36 -> ТПС 245х65х2 | N19: =I34 -> ТПС 200х65х2
A20: 1 | B20: Каркас | I20: ПГС-S 300х80х2 | J20: =[1]Основные!$F$343 -> 1370.25 | K20: 7.913 | L20: шаг5
A21: б | B21: ПГС-сигма 300х80х3 | C21: =I17*(J16)*2 -> 484.49203 | D21: п.м. | E21: ='[2]ПГС и ТПГС'!$H$224 -> 1712.55 | F21: =C21*E21 -> 829716.82 | G21: =C21*H21 -> 5668.5567 | H21: 11.7 | I21: ПГС-S 300х80х2,5 | J21: =[1]Основные!$F$344 -> 1693.65 | K21: 9.668
A22: к | B22: ПГС -сигма 245х80х2,5 | C22: =I17*4*(C10-0.07) -> 308.36 | D22: п.м. | E22: ='[2]ПГС и ТПГС'!$H$204 -> 1289.4 | F22: =C22*E22 -> 397599.38 | G22: =C22*H22 -> 2682.732 | H22: 8.7 | I22: ПГС-S 300х80х3 | J22: =[1]Основные!$F$345 -> 2020.2 | K22: 11.744
A23: р | B23: =I26 -> ПГС 145х70х2 | C23: =3*C9*0 -> 0 | D23: п.м. | E23: =J26 -> 833.7 | H23: =K26 -> 4.82 | I23: ПГС 145х50х1,5 | J23: =[1]Основные!$F$294 -> 532.35 | K23: 3.07
A24: 390/1,51 | B24: ПС 145х45х1,5 | C24: =7*2*2*C9+2*C9*0 -> 1344 | D24: п.м. | E24: =[2]ПС!$D$15 -> 429 | F24: =C24*E24 -> 576576 | G24: =C24*H24 -> 3964.8 | H24: 2.95 | I24: ПГС 145х50х2 | J24: =[1]Основные!$F$295 -> 704.55 | K24: 4.08
A25: с/з | B25: ПП150х1,5 | C25: =2*(C9+1)*0 -> 0 | D25: п.м. | E25: =[3]ПП!$H$42 -> 405.3 | F25: =C25*E25 -> 0 | G25: =C25*H25 -> 0 | H25: 2.7 | I25: ПГС 145х70х1,5 | J25: =[1]Основные!$F$299 -> 630 | K25: 3.64
A26: вод | B26: ПС 145х1,5 | C26: =4*C9 -> 192 | D26: п.м. | E26: =[2]ПС!$H$15 -> 450.45 | F26: =C26*E26 -> 86486.4 | G26: =C26*H26 -> 566.4 | H26: 2.95 | I26: ПГС 145х70х2 | J26: =[1]Основные!$F$301 -> 833.7 | K26: 4.82
A27: тяж | B27: Лист пл. оц. 1мм (тяж) | C27: =I17*2*C8*0.05*1.1*2 -> 51.48 | D27: м2 | E27: ='[2]Профлист,доборы'!$E$24 -> 782.8 | F27: =C27*E27 -> 40298.544 | G27: =C27*H27 -> 409.266 | H27: 7.95
B28: =I43 -> ПШ 61х1 | C28: =2*(C8+2*C10)*1.1 -> 66 | D28: п.м. | E28: ='[2]Профлист,доборы'!$E$64 -> 200 | F28: =C28*E28 -> 13200 | G28: =C28*H28 -> 107.448 | H28: 1.628
B29: Фс11, Фс14 | C29: =I17*(C8+2*C10)/0.6 -> 650 | D29: шт. | E29: =[1]Основные!$D$544 -> 291 | F29: =C29*E29 -> 189150 | G29: =C29*H29 -> 910 | H29: 1.4 | I29: ТПС 150х1,5 | J29: =[1]Основные!$D$259 -> 507 | K29: 2.86
B30: Фс12 | C30: =2*C29 -> 1300 | D30: шт. | E30: =[1]Основные!$D$545 -> 114 | F30: =C30*E30 -> 148200 | G30: =C30*H30 -> 650 | H30: 0.5 | I30: ТПС 150х65х1,5 | J30: =[1]Основные!$D$265 -> 570 | K30: 3.338
B31: Накладные расходы: | C31: 0.02 | F31: =SUM(F21:F30)*C31 -> 45624.543 | I31: ТПС 200х1,5 | J31: =[1]Основные!$D$277 -> 604 | K31: 3.457
B32: Итого каркас | F32: =SUM(F21:F31) -> 2326851.7 | G32: =SUM(G21:G31) -> 14959.203 | I32: ТПС 200х2 | J32: =[1]Основные!$D$278 -> 779 | K32: 4.529 | M32: Прогоны без проц
A33: 2 | B33: Стены | I33: ТПС 200х65х1,5 | J33: =[1]Основные!$D$284 -> 666 | K33: 3.936
B34: ПС 245х65х1,5 | D34: п.м. | E34: =J39 -> 476.7 | F34: =C34*E34 -> 0 | G34: =C34*H34 -> 0 | H34: =K37 -> 1.406 | I34: ТПС 200х65х2 | J34: =[1]Основные!$D$285 -> 882 | K34: 5.164
B35: ПС 245х65х1,2 окр. | C35: =0 -> 0 | D35: п.м. | E35: =1197*1.05 -> 1256.85 | F35: =C35*E35 -> 0 | G35: =C35*H35 -> 0 | H35: 3.7 | I35: ТПС 245х65х1,5 | J35: =[1]Основные!$D$288 -> 753 | K35: 4.473
B36: ПС 145х1,5 окр. | C36: =0 -> 0 | D36: п.м. | E36: =975*1.05 -> 1023.75 | F36: =C36*E36 -> 0 | G36: =C36*H36 -> 0 | H36: 3.66 | I36: ТПС 245х65х2 | J36: =[1]Основные!$D$289 -> 997 | K36: 5.8
B37: ПС 145х1,2 окр. | C37: =0 -> 0 | D37: п.м. | E37: =796*1.05 -> 835.8 | F37: =C37*E37 -> 0 | G37: =C37*H37 -> 0 | H37: 3.09 | I37: ТПП 110х1 | J37: =[1]Основные!$F$215 -> 218.4 | K37: 1.406 | L37: ТПП 110х1,2 | M37: =[1]Основные!$F$216 -> 302.4 | N37: 1.69
B38: У.115 внутр.2м МП | C38: =(3*C9+2*C8)/1.9 -> 94.736842 | D38: шт | E38: ='[4]Профлист,доборы'!$E$42 -> 800 | F38: =C38*E38 -> 75789.474 | G38: =C38*H38 -> 85.263158 | H38: 0.9 | I38: ТПП 150х1 | J38: =[1]Основные!$F$227 -> 262.5 | K38: 1.727
B39: У 115 наруж.2м. МП | C39: =4*C10/1.9 -> 12.631579 | D39: шт. | E39: =E38 -> 800 | F39: =C39*E39 -> 10105.263 | G39: =C39*H39 -> 29.052632 | H39: 2.3 | I39: ТПП 150х1,5 | J39: =[1]Основные!$F$229 -> 476.7 | K39: 2.559 | L39: ТПП 150х1,2 | M39: =[1]Основные!$F$228 -> 362.25 | N39: 2.02
A40: =IF(I3=2,"нар.окр","нар. оц") -> нар.окр | B40: =L54 -> С-18 0,5мм | C40: =(C8*2+C9*2)*(C10+0.5)*1.1*0+C8*2*1.1*0 -> 0 | D40: м2 | E40: ='[5]Профлист,Сайдинг,доборы (МП, (2'!$E$18 -> 550.85 | F40: =E40*C40 -> 0 | G40: =H40*C40 -> 0 | H40: =N54 -> 5.3 | I40: ТПП 200х1 | J40: =[1]Основные!$F$239 -> 318.15 | K40: 2.118
B41: =L64 -> КФ | C41: =IF(I3=J10,2*(C8+C9)*C10*1.2+C9*2.5*1.2,0) -> 0 | D41: м2 | E41: =M64 -> 1868 | F41: =C41*E41 -> 0 | G41: =C41*H41 -> 0 | H41: =O63 -> 5 | I41: ТПС 145х1,5 | J41: =[1]Основные!$F$253 -> 521.85 | K41: 2.8
...

Sheet 15
C1: Предварительная ведомость материалов | H1: Укажите тип обшивки
M2: 2ур | N2: 3ур
H3: наружная | I3: 2
H4: внутренняя | I4: 0 | L4: 3снег | M4: шаг 5 | N4: шаг6
B5: Снег/Ветер : | C5: 3 | D5: 2 | F5: ТЗ № | G5: 10107
A6: место стр | B6: Челябинск | H6: нет обшивки | J6: 0 | L6: 4снег | M6: шаг4 | N6: шаг5
A7: обьект | B7: АТ | F7: =IF(I13=1,"альбом","проект") -> альбом | H7: оцинкованный профлист | J7: 1
B8: Пролет, м : | C8: 15 | F8: ур. отв | G8: 3 | H8: окрашенный профлист | J8: 2 | L8: 5снег | M8: шаг3,5 | N8: шаг4
B9: Длина, м : | C9: 60 | F9: Ст.огн. | G9: 5 | H9: сайдинг (горизонт) | J9: 3
B10: Высота, м : | C10: 6 | H10: фасадная панель (верт.) | J10: 4
A11: шаг рам, м : | C11: 6 | H11: ГВЛ | J11: 5 | M11: прогоны
B12: наружная обшивка : | C12: =IF(I3=0,"нет",IF(I3=1,"оцинкованный профлист",IF(I3=2,"окрашенный профлист",IF(I3=3,"окрашенный профлист, сайдинг","окрашенный профлист, фасадная кассета")))) -> окрашенный профлист | D12: С/П | H12: Альбом-1 | I12: Выбрать 1или 2 | L12: 3 снег | M12: =I32 -> ТПС 200х2 | N12: =I34 -> ТПС 200х65х2
B13: внутренняя обшивка : | C13: =IF(I4=0,"нет",IF(I4=1,"оцинкованный профлист",IF(I4=2,"окрашенный профлист",IF(I4=3,"окрашенный профлист, сайдинг","окрашенный профлист, фасадная панель")))) -> нет | H13: Проект-2 | I13: 1 | J13: расчет балки | L13: 4снег | M13: =I33 -> ТПС 200х65х1,5 | N13: =I32 -> ТПС 200х2
D14: утепление кровли: | E14: 150 | F14: мм | J14: =15*3.14/180 -> 0.26166667 | L14: 5снег | M14: =I32 -> ТПС 200х2 | N14: =I31 -> ТПС 200х1,5
D15: утепление стен: | E15: 100 | F15: мм | J15: =COS(J14) -> 0.96596017
I16: Кол.-во рам | J16: =C8/2/J15*2 -> 15.528591 | N16: кол/б
D17: перегородки | E17: 0 | F17: м2 | I17: =CEILING(C9/C11+1,1) -> 11 | M17: до3м | N17: 2/3 | O17: 2/2,5
A18: МАТЕРИАЛЫ ЗАО "ИНСИ" | I18: эл. Рамы | J18: цена п м | K18: вес пм | L18: 3снег | M18: 6м | N18: 2,5/3 | O18: 2,5/3
A19: № п.п. | B19: наименование | C19: кол-во | D19: ед. изм | E19: цена ед. | F19: цена | G19: общий вес, кг | H19: вес элемента,кг | I19: ПГС-S 300х80х1,5 | J19: =[1]Основные!$F$342 -> 1043.7 | K19: 5.974 | L19: 4снег | M19: до3м | N19: 2/3 | O19: 2/3
A20: 1 | B20: Каркас | I20: ПГС-S 300х80х2 | J20: =[1]Основные!$F$343 -> 1370.25 | K20: 7.913 | M20: 6м | N20: 2,5/3 | O20: 2,5/3
A21: б | B21: =I20 -> ПГС-S 300х80х2 | C21: =I17*(J16)*2 -> 341.62899 | D21: п.м. | E21: =J20 -> 1370.25 | F21: =C21*E21 -> 468117.13 | G21: =C21*H21 -> 2703.3102 | H21: =K20 -> 7.913 | I21: ПГС-S 300х80х3 | J21: =[1]Основные!$F$345 -> 2020.2 | K21: 11.744 | L21: 5снег | M21: до3м | N21: 2/3 | O21: 2/2,5
A22: к | B22: =I20 -> ПГС-S 300х80х2 | C22: =I17*4*(C10-0.07) -> 260.92 | D22: п.м. | E22: =J20 -> 1370.25 | F22: =C22*E22 -> 357525.63 | G22: =C22*H22 -> 2064.66 | H22: =K20 -> 7.913 | I22: ПГС-S 300х80х2,5 | J22: =[1]Основные!$F$344 -> 1693.65 | K22: =9.668 -> 9.668 | M22: 6м | N22: 2,5/3 | O22: 2/3
A23: р | B23: =I26 -> ПГС 145х70х2 | C23: =3*C9+4*C11 -> 204 | D23: п.м. | E23: =J26 -> 833.7 | F23: =E23*C23 -> 170074.8 | G23: =H23*C23 -> 983.28 | H23: =K26 -> 4.82 | I23: ПГС 145х50х1,5 | J23: =[1]Основные!$F$294 -> 532.35 | K23: 3.07
A24: пр | B24: ПС 200х65х2 (2,5м) | C24: =IF(I13=1,8*2*(C9+2*(E15/1000)),9*2*(C9+2*(E15/1000))) -> 963.2 | D24: п.м. | E24: =J34 -> 882 | F24: =C24*E24 -> 849542.4 | G24: =C24*H24 -> 5186.832 | H24: 5.385 | I24: ПГС 145х50х2 | J24: =[1]Основные!$F$295 -> 704.55 | K24: 4.08
A25: с/з | B25: ПП150х1,5 | C25: =IF(I13=1,0,2*(C9+1)) -> 0 | D25: п.м. | E25: =[7]Источник!$F$216 -> 533 | F25: =C25*E25 -> 0 | G25: =C25*H25 -> 0 | H25: =K39 -> 2.559 | I25: ПГС 145х70х1,5 | J25: =[1]Основные!$F$299 -> 630 | K25: 3.64
B26: ПС 145х1,5 водосток | C26: =4*C9 -> 240 | D26: п.м. | E26: =J41 -> 521.85 | F26: =E26*C26 -> 125244 | G26: =H26*C26 -> 672 | H26: =K41 -> 2.8 | I26: ПГС 145х70х2 | J26: =[1]Основные!$F$301 -> 833.7 | K26: 4.82
B27: Лист пл. оц.1мм | C27: =I17*2*C8*0.05*1.1 -> 18.15 | D27: м2 | E27: =[1]Основные!$F$40 -> 1061.312 | F27: =E27*C27 -> 19262.813 | G27: =H27*C27 -> 108.9 | H27: =6 -> 6
B28: =I43 -> ПШ 61х1 | C28: =2*(C8+4*C10)*1.1 -> 85.8 | D28: п.м. | E28: =J43 -> 223 | F28: =E28*C28 -> 19133.4 | G28: =H28*C28 -> 139.854 | H28: =K43 -> 1.63
B29: Фс11, Фс14 | C29: =I17*(C8+2*C10)/0.6 -> 495 | D29: шт. | E29: =[1]Основные!$F$544 -> 291 | F29: =C29*E29 -> 144045 | G29: =C29*H29 -> 693 | H29: 1.4 | I29: ТПС 150х1,5 | J29: =[1]Основные!$D$259 -> 507 | K29: 2.86
B30: Фс12 | C30: =2*C29 -> 990 | D30: шт. | E30: =[1]Основные!$F$545 -> 114 | F30: =C30*E30 -> 112860 | G30: =C30*H30 -> 495 | H30: 0.5 | I30: ТПС 150х65х1,5 | J30: =[1]Основные!$D$265 -> 570 | K30: 3.338
B31: Накладные расходы: | C31: 0.05 | F31: =SUM(F21:F30)*C31 -> 113290.26 | I31: ТПС 200х1,5 | J31: =[1]Основные!$D$277 -> 604 | K31: 3.457
B32: Итого каркас | F32: =SUM(F21:F31) -> 2379095.4 | G32: =SUM(G21:G31) -> 13046.836 | I32: ТПС 200х2 | J32: =[1]Основные!$D$278 -> 779 | K32: 4.529
A33: 2 | B33: Стены | I33: ТПС 200х65х1,5 | J33: =[1]Основные!$D$284 -> 666 | K33: 3.936
A34: нс | B34: =I39 -> ТПП 150х1,5 | C34: =((C10+0.5)/1.2+1)*(C8+C9)*2*1.1 -> 1058.75 | D34: п.м. | E34: =J39 -> 476.7 | H34: =K39 -> 2.559 | I34: ТПС 200х65х2 | J34: =[1]Основные!$D$285 -> 882 | K34: 5.164
A35: сс | B35: ТПС 145х1,5 | C35: =(C8+C9)*2/C11*(C10+0.5)*2*1.1+L151*J151/0.6*O151+(J151+K151)*2*2*L151*1.1 -> 357.5 | D35: п.м. | E35: =J41 -> 521.85 | H35: =K41 -> 2.8 | I35: ТПС 245х65х1,5 | J35: =[1]Основные!$D$288 -> 753 | K35: 4.473
A36: цок (100) | B36: ТПП 150х1 | C36: =2*(C8+C9)*2 -> 300 | D36: п.м. | E36: =J38 -> 262.5 | F36: =E36*C36 -> 78750 | G36: =H36*C36 -> 518.1 | H36: =K38 -> 1.727 | I36: ТПС 245х65х2 | J36: =[1]Основные!$D$289 -> 997 | K36: 5.8
B37: ПШ 40х1 | C37: =IF(I3=J10,C41/0.6,0) -> 0 | D37: п.м. | E37: =J55 -> 0 | F37: =C37*E37 -> 0 | G37: =C37*H37 -> 0 | H37: 1.4 | I37: ТПП 110х1 | J37: =[1]Основные!$F$215 -> 218.4 | K37: 1.406 | L37: ТПП 110х1,2 | M37: =[1]Основные!$F$216 -> 302.4 | N37: 1.69
B38: Уголок 50х50 внутр. (3м) | C38: =(3*C9+2*C8)/1.9 -> 110.52632 | D38: шт. | E38: =J77 -> 736 | F38: =C38*E38 -> 81347.368 | G38: =C38*H38 -> 102.78947 | H38: =L77 -> 0.93 | I38: ТПП 150х1 | J38: =[1]Основные!$F$227 -> 262.5 | K38: 1.727
B39: Уголок 85x85 наружный (2м) | C39: =4*C10/1.9 -> 12.631579 | D39: шт. | E39: =J80 -> 920 | F39: =C39*E39 -> 11621.053 | G39: =C39*H39 -> 29.052632 | H39: =L79 -> 2.3 | I39: ТПП 150х1,5 | J39: =[1]Основные!$F$229 -> 476.7 | K39: 2.559 | L39: ТПП 150х1,2 | M39: =[1]Основные!$F$228 -> 362.25 | N39: 2.02
A40: =IF(I3=2,"нар.окр","нар. оц") -> нар.окр | B40: =L55 -> МП 20 (0,5) | C40: =(C8*2+C9*2)*C10*1.1+C8*3*1.1 -> 1039.5 | D40: п.м. | E40: =M55 -> 787.75 | H40: =O55 -> 5.3 | I40: ТПП 200х1 | J40: =[1]Основные!$F$239 -> 318.15 | K40: 2.118
...

Sheet 18
C1: Предварительная ведомость материалов | H1: Укажите тип обшивки
A3: Проектно-расчетный отдел | H3: наружная | I3: 2
H4: внутренняя | I4: 0
B5: Снег/Ветер : | C5: 3 | D5: 2 | F5: ТЗ № | G5: 11388
A6: место стр | B6: Челябинск | H6: нет обшивки | J6: 0
A7: обьект | B7: АТ | F7: =IF(I13=1,"альбом","проект") -> альбом | H7: оцинкованный профлист | J7: 1
B8: Пролет, м : | C8: 18 | F8: ур. отв | G8: 3 | H8: окрашенный профлист | J8: 2
B9: Длина, м : | C9: 60 | F9: Ст.огн. | G9: 5 | H9: сайдинг (горизонт) | J9: 3
B10: Высота, м : | C10: 6 | H10: фасадная панель (верт.) | J10: 4 | N10: 2ур | O10: 3ур
A11: шаг рам, м : | C11: 6 | H11: ГВЛ | J11: 5
B12: наружная обшивка : | C12: =IF(I3=0,"нет",IF(I3=1,"оцинкованный профлист",IF(I3=2,"окрашенный профлист",IF(I3=3,"окрашенный профлист, сайдинг","окрашенный профлист, фасадная кассета")))) -> окрашенный профлист | D12: С/П | H12: Альбом-1 | I12: Выбрать 1или 2 | M12: 3снег | N12: шаг 4 | O12: шаг5
B13: внутренняя обшивка : | C13: =IF(I4=0,"нет",IF(I4=1,"оцинкованный профлист",IF(I4=2,"окрашенный профлист",IF(I4=3,"окрашенный профлист, сайдинг","окрашенный профлист, фасадная панель")))) -> нет | H13: Проект-2 | I13: 1 | J13: расчет балки
D14: утепление кровли: | E14: 200 | F14: мм | J14: =15*3.14/180 -> 0.26166667 | M14: 4снег | N14: шаг3 | O14: шаг4
D15: утепление стен: | E15: 150 | F15: мм | J15: =COS(J14) -> 0.96596017
I16: Кол.-во рам | J16: =C8/2/J15*2 -> 18.634309 | M16: 5снег | N16: шаг2,5 | O16: шаг3,5
D17: перегородки | E17: 0 | F17: м2 | I17: =CEILING(C9/C11+1,1) -> 11 | L17: ПГС-S 300х80х2,5 | M17: =[1]Основные!$F$344 -> 1693.65 | N17: =9.668 -> 9.668
A18: МАТЕРИАЛЫ ЗАО "ИНСИ" | I18: эл. Рамы | J18: цена п м | K18: вес пм | N18: прогоны
A19: № п.п. | B19: наименование | C19: кол-во | D19: ед. изм | E19: цена ед. | F19: цена | G19: общий вес, кг | H19: вес элемента,кг | I19: ПГС-S 300х80х1,5 | J19: =[1]Основные!$F$342 -> 1043.7 | K19: 5.974 | M19: 3 снег | N19: =I30 -> ТПС 150х65х1,5 | O19: =I31 -> ТПС 200х1,5
A20: 1 | B20: Каркас | I20: ПГС-S 300х80х2 | J20: =[1]Основные!$F$343 -> 1370.25 | K20: 7.913 | M20: 4снег | N20: =I29 -> ТПС 150х1,5 | O20: =I30 -> ТПС 150х65х1,5
A21: б | B21: =I21 -> ПГС-S 300х80х3 | C21: =I17*(J16)*2 -> 409.95479 | D21: п.м. | E21: =J21 -> 2020.2 | F21: =C21*E21 -> 828190.67 | G21: =C21*H21 -> 4814.5091 | H21: =K21 -> 11.744 | I21: ПГС-S 300х80х3 | J21: =[1]Основные!$F$345 -> 2020.2 | K21: 11.744 | M21: 5снег | N21: =I30 -> ТПС 150х65х1,5 | O21: =I31 -> ТПС 200х1,5
A22: к | B22: =I21 -> ПГС-S 300х80х3 | C22: =I17*4*(C10-0.07) -> 260.92 | D22: п.м. | E22: =J21 -> 2020.2 | F22: =C22*E22 -> 527110.58 | G22: =C22*H22 -> 3064.2445 | H22: =K21 -> 11.744 | I22: ПГС 145х50х1,5 | J22: =[1]Основные!$F$294 -> 532.35 | K22: 3.07
A23: р | B23: =I24 -> ПГС 145х70х1,5 | C23: =(3*C9+8*C11) -> 228 | D23: п.м. | E23: =J24 -> 630 | H23: =K24 -> 3.64 | I23: ПГС 145х50х2 | J23: =[1]Основные!$F$295 -> 704.55 | K23: 4.08 | M23: 3сн | N23: 2,5/3 | O23: 2,5/3 | P23: 6м
A24: пр | B24: ПС 245х65х2 (3м) | C24: =IF(I13=1,8*2*(C9),9*2*(C9)) -> 960 | D24: п.м. | E24: =J36 -> 997 | F24: =C24*E24 -> 957120 | G24: =C24*H24 -> 5846.88 | H24: 6.0905 | I24: ПГС 145х70х1,5 | J24: =[1]Основные!$F$299 -> 630 | K24: 3.64 | N24: 2/3 | O24: 2/3 | P24: 3м
A25: с/з | B25: ПП150х1,5 | C25: =IF(I13=1,0,2*(C9+1)) -> 0 | D25: п.м. | E25: =J39 -> 476.7 | F25: =C25*E25 -> 0 | G25: =C25*H25 -> 0 | H25: =K39 -> 2.559 | I25: ПГС 145х70х2 | J25: =[1]Основные!$F$301 -> 833.7 | K25: 4.82 | M25: 4сн | N25: 2/3 | O25: 2,5/3
B26: Лист пл. оц.1мм | C26: =I17*2*C8*0.05*1.1 -> 21.78 | D26: м2 | E26: =[1]Основные!$F$40 -> 1061.312 | F26: =C26*E26 -> 23115.375 | G26: =C26*H26 -> 130.68 | H26: =6 -> 6 | N26: 2/2,5 | O26: 2/2,5
B27: ПШ 61х1 | C27: =2*(C8+2*C10)*1.1 -> 66 | D27: п.м. | E27: =J43 -> 223 | F27: =C27*E27 -> 14718 | G27: =C27*H27 -> 107.58 | H27: =1.63 -> 1.63 | M27: 5сн | N27: 2,5/3 | O27: 2/3
A28: водосток | B28: ПС 145х1,5 | C28: =4*C9 -> 240 | D28: п.м. | E28: =J41 -> 521.85 | F28: =C28*E28 -> 125244 | G28: =C28*H28 -> 672 | H28: =K41 -> 2.8 | N28: 2/3 | O28: 2/3
B29: Фс11, Фс14 | C29: =I17*(C8+2*C10)/0.6 -> 550 | D29: шт. | E29: =[1]Основные!$F$544 -> 291 | F29: =C29*E29 -> 160050 | G29: =C29*H29 -> 770 | H29: 1.4 | I29: ТПС 150х1,5 | J29: =[1]Основные!$D$259 -> 507 | K29: 2.86
B30: Фс12 | C30: =2*C29 -> 1100 | D30: шт. | E30: =[1]Основные!$F$545 -> 114 | F30: =C30*E30 -> 125400 | G30: =C30*H30 -> 550 | H30: 0.5 | I30: ТПС 150х65х1,5 | J30: =[1]Основные!$D$265 -> 570 | K30: 3.338
B31: Накладные расходы: | C31: 0.05 | F31: =SUM(F21:F30)*C31 -> 138047.43 | I31: ТПС 200х1,5 | J31: =[1]Основные!$D$277 -> 604 | K31: 3.457
B32: Итого каркас | F32: =SUM(F21:F31) -> 2898996.1 | G32: =SUM(G21:G31) -> 15955.894 | I32: ТПС 200х2 | J32: =[1]Основные!$D$278 -> 779 | K32: 4.529
A33: 2 | B33: Стены | I33: ТПС 200х65х1,5 | J33: =[1]Основные!$D$284 -> 666 | K33: 3.936
A34: нс | B34: ПС 145х1,5 | C34: =((C10+0.5)/1.2+1)*(C8+C9)*2*1.1*2 -> 2202.2 | D34: п.м. | E34: =J41 -> 521.85 | H34: =K41 -> 2.8 | I34: ТПС 200х65х2 | J34: =[1]Основные!$D$285 -> 882 | K34: 5.164
A35: сс | B35: ТПС 145х1,5 | C35: =0*(C8+C9)*2/C11*(C10+0.5)*2*1.1+L153*J153/0.6*O153+(J153+K153)*2*2*L153*1.1 -> 0 | D35: п.м. | E35: =J41 -> 521.85 | H35: =K41 -> 2.8 | I35: ТПС 245х65х1,5 | J35: =[1]Основные!$D$288 -> 753 | K35: 4.473
A36: цок (100) | B36: ТПП 150х1 | C36: =2*(C8+C9)*2 -> 312 | D36: п.м. | E36: =J38 -> 262.5 | H36: =K38 -> 1.727 | I36: ТПС 245х65х2 | J36: =[1]Основные!$D$289 -> 997 | K36: 5.8 | L36: ТПП 110х1,2 | M36: =[1]Основные!$F$216 -> 302.4 | N36: 1.69
B37: ПШ 40х1 | C37: =IF(I3=J10,C41/0.6,0) -> 0 | D37: п.м. | E37: =J45 -> 190 | F37: =C37*E37 -> 0 | G37: =C37*H37 -> 0 | H37: 1.4 | I37: ТПП 110х1 | J37: =[1]Основные!$F$215 -> 218.4 | K37: 1.406
B38: Уголок 50х50 внутр. (3м) | C38: =(3*C9+2*C8)/2.9 -> 74.482759 | D38: шт. | E38: =J77 -> 736 | F38: =C38*E38 -> 54819.31 | G38: =C38*H38 -> 69.268966 | H38: =L77 -> 0.93 | I38: ТПП 150х1 | J38: =[1]Основные!$F$227 -> 262.5 | K38: 1.727 | L38: ТПП 150х1,2 | M38: =[1]Основные!$F$228 -> 362.25 | N38: 2.02
B39: Уголок 85x85 наружный (3м) | C39: =4*C10/1.9 -> 12.631579 | D39: шт. | E39: =J80 -> 920 | F39: =C39*E39 -> 11621.053 | G39: =C39*H39 -> 29.052632 | H39: =L79 -> 2.3 | I39: ТПП 150х1,5 | J39: =[1]Основные!$F$229 -> 476.7 | K39: 2.559
A40: =IF(I3=2,"нар.окр","нар. оц") -> нар.окр | B40: =L45 -> МП 20 (0,5) | C40: =(C9*2+C8*2)*(C10+0.5)*1.1+C8*2.5*1.1 -> 1164.9 | D40: м2 | E40: =M45 -> 787.75 | H40: =O45 -> 5.3 | I40: ТПП 200х1 | J40: =[1]Основные!$F$239 -> 318.15 | K40: 2.118
F41: =C41*E41 -> 0 | G41: =C41*H41 -> 0 | H41: =O50 -> 5 | I41: ТПС 145х1,5 | J41: =[1]Основные!$F$253 -> 521.85 | K41: 2.8
...

Sheet 21
C1: Предварительная ведомость материалов | H1: Укажите тип обшивки
A3: Проектно-расчетный отдел | H3: наружная | I3: 2
H4: внутренняя | I4: 2
B5: Снег/Ветер : | C5: 3 | D5: 2 | F5: ТЗ № | G5: 10108
A6: место стр | B6: Челябинск | H6: нет обшивки | J6: 0
A7: обьект | B7: Ангар | F7: =IF(I13=1,"альбом","проект") -> альбом | H7: оцинкованный профлист | J7: 1
B8: Пролет, м : | C8: 21 | F8: ур. отв | G8: 3 | H8: окрашенный профлист | J8: 2
B9: Длина, м : | C9: 60 | F9: Ст.огн. | G9: 5 | H9: сайдинг (горизонт) | J9: 3 | M9: шаг
B10: Высота, м : | C10: 6 | H10: фасадная панель (верт.) | J10: 4 | M10: 2ур | N10: 3ур
A11: шаг рам, м : | C11: 4 | H11: ГВЛ | J11: 5 | L11: 3снег | M11: 3 | N11: 4
B12: наружная обшивка : | C12: =IF(I3=0,"нет",IF(I3=1,"оцинкованный профлист",IF(I3=2,"окрашенный профлист",IF(I3=3,"окрашенный профлист, сайдинг","окрашенный профлист, фасадная кассета")))) -> окрашенный профлист | H12: Альбом-1 | I12: Выбрать 1или 2 | L12: 4 снег | M12: 2.5 | N12: 3
B13: внутренняя обшивка : | C13: =IF(I4=0,"нет",IF(I4=1,"оцинкованный профлист",IF(I4=2,"окрашенный профлист",IF(I4=3,"окрашенный профлист, сайдинг","окрашенный профлист, фасадная панель")))) -> окрашенный профлист | H13: Проект-2 | I13: 1 | J13: расчет балки | L13: 5 снег | M13: 2 | N13: 2.5
D14: утепление кровли: | E14: 200 | F14: мм | J14: =15*3.14/180 -> 0.26166667
D15: утепление стен: | E15: 150 | F15: мм | J15: =COS(J14) -> 0.96596017 | L15: 3 снег | M15: 2/3 | N15: 2/3 | O15: 3м
I16: Кол.-во рам | J16: =C8/2/J15*2 -> 21.740027 | M16: 2,5/3 | N16: 2,5/3 | O16: 6м
D17: перегородки | E17: 0 | F17: м2 | I17: =CEILING(C9/C11+1,1) -> 16 | L17: 4 снег | M17: 2/3 | N17: 2/3 | O17: 3м
A18: МАТЕРИАЛЫ ЗАО "ИНСИ" | I18: эл. Рамы | J18: цена п м | K18: вес пм | M18: 2,5/3 | N18: 2,5/3 | O18: 6м
A19: № п.п. | B19: наименование | C19: кол-во | D19: ед. изм | E19: цена ед. | F19: цена | G19: общий вес, кг | H19: вес элемента,кг | I19: ПГС-S 300х80х1,5 | J19: =[1]Основные!$F$342 -> 1043.7 | K19: 5.974 | L19: 5 снег | M19: 2/3 | N19: 2/3 | O19: 3м
A20: 1 | B20: Каркас | I20: ПГС-S 300х80х2 | J20: =[1]Основные!$F$343 -> 1370.25 | K20: 7.913 | M20: 2,5/3 | N20: 2,5/3 | O20: 6м
A21: б | B21: =I21 -> ПГС-S 300х80х3 | C21: =I17*(J16)*2 -> 695.68086 | D21: п.м. | E21: =J21 -> 2020.2 | F21: =C21*E21 -> 1405414.5 | G21: =C21*H21 -> 8170.076 | H21: =K21 -> 11.744 | I21: ПГС-S 300х80х3 | J21: =[1]Основные!$F$345 -> 2020.2 | K21: 11.744
A22: к | B22: =I20 -> ПГС-S 300х80х2 | C22: =I17*4*(C10-0.07) -> 379.52 | D22: п.м. | E22: =J20 -> 1370.25 | F22: =C22*E22 -> 520037.28 | G22: =H22*C22 -> 3003.1418 | H22: =K20 -> 7.913 | I22: ПГС 145х50х1,5 | J22: =[1]Основные!$F$294 -> 532.35 | K22: 3.07 | L22: 3 снег | M22: =I29 -> ТПС 150х1,5 | N22: =M22 -> ТПС 150х1,5
A23: р | B23: =I25 -> ПГС 145х70х2 | C23: =5*C9+4*C11 -> 316 | D23: п.м. | E23: =J25 -> 833.7 | F23: =C23*E23 -> 263449.2 | G23: =H23*C23 -> 1523.12 | H23: =K25 -> 4.82 | I23: ПГС 145х50х2 | J23: =[1]Основные!$F$295 -> 704.55 | K23: 4.08 | L23: 4 снег | M23: =I29 -> ТПС 150х1,5 | N23: =I29 -> ТПС 150х1,5 | O23: шаг прогонов 1,5
A24: пр | B24: =I31 -> ТПС 200х1,5 | C24: =IF(I13=1,16*2*(C9+2*E15/1000),17*2*(C9+2*E15/1000)) -> 1929.6 | D24: п.м. | E24: =J31 -> 604 | F24: =C24*E24 -> 1165478.4 | G24: =C24*H24 -> 6670.6272 | H24: =K31 -> 3.457 | I24: ПГС 145х70х1,5 | J24: =[1]Основные!$F$299 -> 630 | K24: 3.64 | L24: 5 снег | M24: =I30 -> ТПС 150х65х1,5 | N24: =I29 -> ТПС 150х1,5
A25: с/з | B25: ПП150х1,5 | C25: =IF(I13=1,0,2*(C9+1)) -> 0 | D25: п.м. | E25: =J39 -> 476.7 | F25: =C25*E25 -> 0 | G25: =C25*H25 -> 0 | H25: =K39 -> 2.559 | I25: ПГС 145х70х2 | J25: =[1]Основные!$F$301 -> 833.7 | K25: 4.82 | L25: ПГС-S 300х80х2,5 | M25: =[1]Основные!$F$344 -> 1693.65 | N25: 9.668
B26: =I43 -> ПШ 61х1 | C26: =2*(C8+2*C10)*1.1 -> 72.6 | D26: п.м. | E26: =J43 -> 223 | F26: =C26*E26 -> 16189.8 | G26: =C26*H26 -> 118.338 | H26: =K43 -> 1.63
B27: Лист пл оц 1мм (тяж) | C27: =2*C8*0.05*I17 -> 33.6 | D27: м2 | E27: =[1]Основные!$F$40 -> 1061.312 | F27: =C27*E27 -> 35660.083 | G27: =C27*H27 -> 201.6 | H27: 6
A28: водосток | B28: ПС 145х1,5 | C28: =4*C9 -> 240 | D28: п.м. | E28: =J41 -> 521.85 | H28: =K41 -> 2.8
B29: Фс11, Фс14 | C29: =I17*(C8+2*C10)/0.6 -> 880 | D29: шт. | E29: =[1]Основные!$F$544 -> 291 | F29: =C29*E29 -> 256080 | G29: =C29*H29 -> 1232 | H29: 1.4 | I29: ТПС 150х1,5 | J29: =[1]Основные!$D$259 -> 507 | K29: 2.86
B30: Фс12 | C30: =2*C29 -> 1760 | D30: шт. | E30: =[1]Основные!$F$545 -> 114 | F30: =C30*E30 -> 200640 | G30: =C30*H30 -> 880 | H30: 0.5 | I30: ТПС 150х65х1,5 | J30: =[1]Основные!$D$265 -> 570 | K30: 3.338
B31: Накладные расходы: | C31: 0.05 | F31: =SUM(F21:F30)*C31 -> 193147.46 | I31: ТПС 200х1,5 | J31: =[1]Основные!$D$277 -> 604 | K31: 3.457
B32: Итого каркас | F32: =SUM(F21:F31) -> 4056096.7 | G32: =SUM(G21:G31) -> 21798.903 | I32: ТПС 200х2 | J32: =[1]Основные!$D$278 -> 779 | K32: 4.529
A33: 2 | B33: Стены | I33: ТПС 200х65х1,5 | J33: =[1]Основные!$D$284 -> 666 | K33: 3.936
A34: нс | B34: ТПП 150х1,2 | C34: =((C10+0.5)/1.2+1)*(C8+C9)*2*1.1 -> 1143.45 | D34: п.м. | E34: =M38 -> 362.25 | F34: =M38 -> 362.25 | G34: =H34*C34 -> 2309.769 | H34: =N38 -> 2.02 | I34: ТПС 200х65х2 | J34: =[1]Основные!$D$285 -> 882 | K34: 5.164
A35: сс | B35: =I41 -> ТПС 145х1,5 | C35: =(C8+C9)*2/C11*(C10+0.5)*2*1.1+L142*J142/0.6*O142+(J142+K142)*2*2*L142*1.1 -> 579.15 | D35: п.м. | E35: =J41 -> 521.85 | F35: =E35*C35 -> 302229.43 | G35: =H35*C35 -> 1621.62 | H35: =K41 -> 2.8 | I35: ТПС 245х65х1,5 | J35: =[1]Основные!$D$288 -> 753 | K35: 4.473
A36: цок (100) | B36: ТПП 150х1 | C36: =2*(C8+C9)*2*1.1 -> 356.4 | D36: п.м. | E36: =J38 -> 262.5 | F36: =C36*E36 -> 93555 | G36: =C36*H36 -> 615.5028 | H36: =K38 -> 1.727 | I36: ТПС 245х65х2 | J36: =[1]Основные!$D$289 -> 997 | K36: 5.8
B37: ПШ 40х1 | C37: =IF(I3=J10,C41/0.6,0) -> 0 | D37: п.м. | E37: =J45 -> 190 | F37: =C37*E37 -> 0 | G37: =C37*H37 -> 0 | H37: 1.4 | I37: ТПП 110х1 | J37: =[1]Основные!$F$215 -> 218.4 | K37: 1.406 | L37: ТПП 110х1,2 | M37: =[1]Основные!$F$216 -> 302.4 | N37: 1.69
B38: Уголок 50х50 внутр. (3м) | C38: =(3*C9+2*C8)/2.9 -> 76.551724 | D38: шт. | E38: =J67 -> 736 | F38: =C38*E38 -> 56342.069 | G38: =C38*H38 -> 71.193103 | H38: =L67 -> 0.93 | I38: ТПП 150х1 | J38: =[1]Основные!$F$227 -> 262.5 | K38: 1.727 | L38: ТПП 150х1,2 | M38: =[1]Основные!$F$228 -> 362.25 | N38: 2.02
B39: Уголок 85x85 наружный (2м) | C39: =4*C10/1.9 -> 12.631579 | D39: шт. | E39: =J70 -> 920 | F39: =C39*E39 -> 11621.053 | G39: =C39*H39 -> 29.052632 | H39: =L69 -> 2.3 | I39: ТПП 150х1,5 | J39: =[1]Основные!$F$229 -> 476.7 | K39: 2.559
A40: =IF(I3=2,"нар.окр","нар. оц") -> нар.окр | B40: =L45 -> МП 20 0,45 | C40: =(C8*2+C9*2)*(C10+0.5)*1.1+C8*3*1.1 -> 1227.6 | D40: п.м. | E40: =M45 -> 787.75 | F40: =E40*C40 -> 967041.9 | G40: =H40*C40 -> 6506.28 | H40: =O45 -> 5.3 | I40: ТПП 200х1 | J40: =[1]Основные!$F$239 -> 318.15 | K40: 2.118
B41: ПФ 0,7мм | C41: =IF(I3=J10,2*(C8+C9)*C10*1.2+C9*2.5*1.2,0) -> 0 | D41: м2 | E41: =M50 -> 1255 | H41: =O50 -> 5 | I41: ТПС 145х1,5 | J41: =[1]Основные!$F$253 -> 521.85 | K41: 2.8
...

Sheet 1ск
C1: Предварительная ведомость материалов | H1: Укажите тип обшивки
A3: Проектно-расчетный отдел | H3: наружная | I3: 2
H4: внутренняя | I4: 2
B5: Снег/Ветер : | C5: 3 | D5: 2 | F5: ТЗ № | G5: 10256
A6: место стр | B6: Челябинск | H6: нет обшивки | J6: 0
A7: обьект | B7: Ангар | F7: =IF(I13=1,"альбом","проект") -> альбом | H7: оцинкованный профлист | J7: 1
B8: Пролет, м : | C8: 12 | F8: ур. отв | G8: 3 | H8: окрашенный профлист | J8: 2
B9: Длина, м : | C9: 60 | F9: Ст.огн. | G9: 5 | H9: сайдинг (горизонт) | J9: 3
B10: Высота, м : | C10: 6 | H10: фасадная панель (верт.) | J10: 4
A11: шаг рам, м : | C11: 6 | H11: ГВЛ | J11: 5
B12: наружная обшивка : | C12: =IF(I3=0,"нет",IF(I3=1,"оцинкованный профлист",IF(I3=2,"окрашенный профлист",IF(I3=3,"окрашенный профлист, сайдинг","окрашенный профлист, фасадная кассета")))) -> окрашенный профлист | H12: Альбом-1 | I12: Выбрать 1или 2
B13: внутренняя обшивка : | C13: =IF(I4=0,"нет",IF(I4=1,"оцинкованный профлист",IF(I4=2,"окрашенный профлист",IF(I4=3,"окрашенный профлист, сайдинг","окрашенный профлист, фасадная панель")))) -> окрашенный профлист | H13: Проект-2 | I13: 1 | J13: расчет балки | K13: расчет стойки
D14: утепление кровли: | E14: 200 | F14: мм | J14: =10*3.14/180 -> 0.17444444 | K14: =SIN(J14) -> 0.17356104
D15: утепление стен: | E15: 150 | F15: мм | J15: =COS(J14) -> 0.98482311 | K15: =K14*J16 -> 2.114829
I16: Кол.-во рам | J16: =C8/J15 -> 12.184929 | K16: =C10+K15 -> 8.114829
D17: перегородки | E17: 0 | F17: м2 | I17: =CEILING(C9/C11+1,1) -> 11
A18: МАТЕРИАЛЫ ЗАО "ИНСИ" | I18: эл. Рамы | J18: цена п м | K18: вес пм
A19: № п.п. | B19: наименование | C19: кол-во | D19: ед. изм | E19: цена ед. | F19: цена | G19: общий вес, кг | H19: вес элемента,кг | I19: ПГС-S 300х80х1,5 | J19: =[1]Основные!$F$342 -> 1043.7 | K19: 5.974
A20: 1 | B20: Каркас | I20: ПГС-S 300х80х2 | J20: =[1]Основные!$F$343 -> 1370.25 | K20: 7.913 | L20: ПГС-S 300х80х2,5 | M20: =[1]Основные!$F$344 -> 1693.65 | N20: =9.668 -> 9.668
A21: б | B21: =I20 -> ПГС-S 300х80х2 | C21: =I17*(J16)*2 -> 268.06844 | D21: п.м. | E21: =J20 -> 1370.25 | F21: =C21*E21 -> 367320.79 | G21: =C21*H21 -> 2121.2256 | H21: =K20 -> 7.913 | I21: ПГС-S 300х80х3 | J21: =[1]Основные!$F$345 -> 2020.2 | K21: 11.744
A22: к | B22: =I20 -> ПГС-S 300х80х2 | C22: =I17*(2*(C10+0.5)+2*(K16+0.5)) -> 332.52624 | D22: п.м. | E22: =J20 -> 1370.25 | F22: =C22*E22 -> 455644.08 | G22: =C22*H22 -> 2631.2801 | H22: =K20 -> 7.913 | I22: ПГС 145х50х1,5 | J22: =[1]Основные!$F$294 -> 532.35 | K22: 3.07
A23: р | B23: =I22 -> ПГС 145х50х1,5 | C23: =3*C9 -> 180 | D23: п.м. | E23: =J22 -> 532.35 | H23: =K25 -> 4.82 | I23: ПГС 145х50х2 | J23: =[1]Основные!$F$295 -> 704.55 | K23: 4.08
A24: пр | B24: =I34 -> ТПС 200х65х2 | C24: =IF(I13=1,10*2*(C9+1),11*2*(C9+1)) -> 1220 | D24: п.м. | E24: =J33 -> 666 | F24: =C24*E24 -> 812520 | G24: =C24*H24 -> 4801.92 | H24: =K33 -> 3.936 | I24: ПГС 145х70х1,5 | J24: =[1]Основные!$F$299 -> 630 | K24: 3.64
A25: с/з | B25: ПП150х1,5 | C25: =IF(I13=1,0,2*(C9+1)) -> 0 | D25: п.м. | E25: =J39 -> 476.7 | F25: =C25*E25 -> 0 | G25: =C25*H25 -> 0 | H25: =K39 -> 2.559 | I25: ПГС 145х70х2 | J25: =[1]Основные!$F$301 -> 833.7 | K25: 4.82
A26: вод | B26: ПС 145х1,5 | C26: =4*C9 -> 240 | D26: п.м. | E26: =J41 -> 521.85 | H26: =3 -> 3
B27: Лист пл . Оц. 1мм (тяж) | C27: =I17*(2*C8*0.05)*1.1 -> 14.52 | D27: м2 | E27: =[1]Основные!$F$40 -> 1061.312 | H27: 6
B28: ПШ 61х1 | C28: =2*(C8+2*C10)*1.1 -> 52.8 | D28: п.м. | E28: =J43 -> 223 | H28: =K43 -> 1.63
B29: Фс11, Фс14 | C29: =I17*(C8+2*C10)/0.6 -> 440 | D29: шт. | E29: =[1]Основные!$F$544 -> 291 | F29: =C29*E29 -> 128040 | G29: =C29*H29 -> 616 | H29: 1.4 | I29: ТПС 150х1,5 | J29: =[1]Основные!$D$259 -> 507 | K29: 2.86
B30: Фс12 | C30: =2*C29 -> 880 | D30: шт. | E30: =[1]Основные!$F$545 -> 114 | F30: =C30*E30 -> 100320 | G30: =C30*H30 -> 440 | H30: 0.5 | I30: ТПС 150х65х1,5 | J30: =[1]Основные!$D$265 -> 570 | K30: 3.338
B31: Накладные расходы: | C31: 0.05 | F31: =SUM(F21:F30)*C31 -> 93192.243 | I31: ТПС 200х1,5 | J31: =[1]Основные!$D$277 -> 604 | K31: 3.457
B32: Итого каркас | F32: =SUM(F21:F31) -> 1957037.1 | G32: =SUM(G21:G31) -> 10610.426 | I32: ТПС 200х2 | J32: =[1]Основные!$D$278 -> 779 | K32: 4.529
A33: 2 | B33: Стены | I33: ТПС 200х65х1,5 | J33: =[1]Основные!$D$284 -> 666 | K33: 3.936
A34: нс | B34: =I39 -> ТПП 150х1,5 | C34: =(C10/1.2+1)*(C8+C9)*2*1.1 -> 950.4 | D34: п.м. | E34: =J41 -> 521.85 | F34: =C34*E34 -> 495966.24 | G34: =C34*H34 -> 2851.2 | H34: 3 | I34: ТПС 200х65х2 | J34: =[1]Основные!$D$285 -> 882 | K34: 5.164
A35: сс | B35: ТПС 145х1,5 | C35: =(C8+C9)*2/C11*C10*2*1.1+L141*J141/0.6*O141+(J141+K141)*2*2*L141*1.1 -> 316.8 | D35: п.м. | E35: =J41 -> 521.85 | F35: =C35*E35 -> 165322.08 | G35: =C35*H35 -> 887.04 | H35: =K41 -> 2.8 | I35: ТПС 245х65х1,5 | J35: =[1]Основные!$D$288 -> 753 | K35: 4.473
A36: цок | B36: ТПП 150х1 | C36: =2*(C8+C9)*2 -> 288 | D36: п.м. | E36: =J38 -> 262.5 | H36: =K38 -> 1.727 | I36: ТПС 245х65х2 | J36: =[1]Основные!$D$289 -> 997 | K36: 5.8
B37: =I43 -> ПШ 61х1 | C37: =IF(I3=J10,C41/0.6,0) -> 0 | D37: п.м. | E37: =J43 -> 223 | F37: =C37*E37 -> 0 | G37: =C37*H37 -> 0 | H37: =K43 -> 1.63 | I37: ТПП 110х1 | J37: =[1]Основные!$F$215 -> 218.4 | K37: 1.406 | L37: ТПП 110х1,2 | M37: =[1]Основные!$F$216 -> 302.4 | N37: 1.69
B38: Уголок 50х50 внутр. (3м) | C38: =(3*C9+2*C8)/2.9 -> 70.344828 | D38: шт. | E38: =[7]Источник!$F$491 -> 445 | F38: =C38*E38 -> 31303.448 | G38: =C38*H38 -> 65.42069 | H38: =L67 -> 0.93 | I38: ТПП 150х1 | J38: =[1]Основные!$F$227 -> 262.5 | K38: 1.727
B39: Уголок 85x85 наружный (2м) | C39: =4*C10/1.9 -> 12.631579 | D39: шт. | E39: =[7]Источник!$F$500 -> 339,5 | F39: =C39*E39 -> 4288.4211 | G39: =C39*H39 -> 29.052632 | H39: =L69 -> 2.3 | I39: ТПП 150х1,5 | J39: =[1]Основные!$F$229 -> 476.7 | K39: 2.559 | L39: ТПП 150х1,2 | M39: =[1]Основные!$F$228 -> 362.25 | N39: 2.02
A40: =IF(I3=2,"нар.окр","нар. оц") -> нар.окр | B40: =L45 -> МП 20 0,5мм | C40: =(C8*2+C9*2)*C10*1.1+C8*2*1.1+C9*2*1.1 -> 1108.8 | D40: п.м. | E40: =N45 -> 590.4445 | F40: =C40*E40 -> 654684.86 | G40: =C40*H40 -> 5876.64 | H40: =O45 -> 5.3 | I40: ТПП 200х1 | J40: =[1]Основные!$F$239 -> 318.15 | K40: 2.118
B41: =L51 -> КФ | C41: =IF(I3=J10,2*(C8+C9)*C10*1.2+C9*2.5*1.2,0) -> 0 | D41: м2 | E41: =M51 -> 1868 | H41: =O50 -> 5 | I41: ТПС 145х1,5 | J41: =[1]Основные!$F$253 -> 521.85 | K41: 2.8
...
