Workbook

Sheet Лист1
A2: Город | B2: Новый уренгой
A3: Ур. отв | B3: 1
A5: Общие данные | H5: А | M5: Iа
A6: высота окна | B6: 1 | C6: м | H6: В | M6: I
A7: шаг рам | B7: 6 | C7: м | F7: вертикальная | G7: горизонтальная | H7: С | M7: II
A8: тип окна | B8: 1 | E8: к-т приведения момента | F8: =INDEX(J34:J38,MATCH(B8,I34:I38,0),1) -> 0.125 | G8: 0.125 | M8: III
A9: Высота здания | B9: 6 | C9: м | H9: новым | J9: по СП РК EN | M9: IV
A10: Пролет здания | B10: 18 | C10: м | H10: старым | J10: по СП 20.13330.20ХХ | M10: V
A11: Длина здания | B11: 42 | C11: м | M11: VI
H12: односкатная | J12: 1.1 | M12: VII
A13: Нагрузки | H13: двускатная | J13: 1 | M13: VIII | P13: 1ый стеклопакет | Q13: =1*25*1.2 -> 30
A14: тип местности | B14: А | J14: 0.8 | P14: 2ой стеклопакет | Q14: =1*35*1.2 -> 42
A15: ветровая нагрузка, кПа | B15: =IF(J19="да",IF(D15="по СП РК EN",INDEX('[1]СП РК EN'!$I$3:$I$1000,MATCH(B2,'[1]СП РК EN'!$B$3:$B$1000,0),1),INDEX('[1]СП РК EN'!$H$3:$H$1000,MATCH(B2,'[1]СП РК EN'!$B$3:$B$1000,0),1)),INDEX('[1]СП 20'!$G$3:$G$1000,MATCH(B2,'[1]СП 20'!$B$3:$B$1000,0),1)) -> 0.38 | C15: по | D15: по СП 20.13330.20ХХ | P15: 3ой стеклопакет | Q15: =1*45*1.2 -> 54
M16: нет
A17: конструкция окна | B17: 2ой стеклопакет | C17: нагрузка | D17: =INDEX(Q13:Q15,MATCH(B17,P13:P15,0),1)/100 -> 0.42 | E17: кПа | J17: чек на казахов)) | M17: 1
J18: =INDEX('[1]СП РК EN'!$C$3:$C$1000,MATCH(B2,'[1]СП РК EN'!$B$3:$B$1000,0),1) -> #N/A | K18: =IFERROR(J18,"нет") -> нет | M18: 2
I19: КЗ??? | J19: =IF(K18="нет","нет","да") -> нет | M19: 3
A20: Макс. к-т исп. | B20: 0.85
A22: Подобранное сечение нижнего ригеля для типов 1-5 и верхнего ригеля для типов 2-5
A23: № | B23: Сечение | C23: Сталь | D23: Вес одного ригеля, кг
A24: 1 | B24: =Расчет!B22 -> кв.120х3 | C24: =Расчет!B23 -> С245 | D24: =Расчет!B21 -> 66.0016
A25: 2 | B25: =Расчет!C22 -> кв.120х3 | C25: =Расчет!C23 -> С345 | D25: =Расчет!C21 -> 66.0148
A26: 3 | B26: =Расчет!D22 -> кв.120х4 | C26: =Расчет!D23 -> С245 | D26: =Расчет!D21 -> 87.0017
A27: 4 | B27: =Расчет!E22 -> пр.140х100х4 | C27: =Расчет!E23 -> С245 | D27: =Расчет!E21 -> 87.0078
A28: 5 | B28: =Расчет!F22 -> кв.120х4 | C28: =Расчет!F23 -> С345 | D28: =Расчет!F21 -> 87.0149
A29: 6 | B29: =Расчет!G22 -> пр.140х100х4 | C29: =Расчет!G23 -> С345 | D29: =Расчет!G21 -> 87.021
A30: 7 | B30: =Расчет!H22 -> пр.140х100х4 90° | C30: =Расчет!H23 -> С245 | D30: =Расчет!H21 -> 87.0283
A31: 8 | B31: =Расчет!I22 -> пр.140х100х4 90° | C31: =Расчет!I23 -> С345 | D31: =Расчет!I21 -> 87.0356
A32: 9 | B32: =Расчет!J22 -> кв.100х5 | C32: =Расчет!J23 -> С245 | D32: =Расчет!J21 -> 88.8013
A33: 10 | B33: =Расчет!K22 -> кв.100х5 | C33: =Расчет!K23 -> С345 | D33: =Расчет!K21 -> 88.8145 | J33: момент | K33: длина | L33: прогибы
I34: 1 | J34: 0.125 | K34: 1 | L34: 1
A35: Подобранное сечение верхнего ригеля для типа 1 | I35: 2 | J35: 0.055 | K35: =5/6 -> 0.83333333 | L35: 0.13
A36: № | B36: Сечение | C36: Сталь | D36: Вес одного ригеля, кг | I36: 3 | J36: 0.062 | K36: 0.33 | L36: 0.24
A37: 1 | B37: =Расчет!B27 -> кв.100х3 | C37: =Расчет!B28 -> С245 | D37: =Расчет!B26 -> 54.6011 | I37: 4 | J37: 0.078 | K37: 0.5 | L37: 0.5
A38: 2 | B38: =Расчет!C27 -> кв.100х3 | C38: =Расчет!C28 -> С345 | D38: =Расчет!C26 -> 54.6143 | I38: 5 | J38: 0.073 | K38: 0.75 | L38: 0.2
A39: 3 | B39: =Расчет!D27 -> пр.120х80х3 90° | C39: =Расчет!D28 -> С245 | D39: =Расчет!D26 -> 54.6274
A40: 4 | B40: =Расчет!E27 -> пр.120х80х3 90° | C40: =Расчет!E28 -> С345 | D40: =Расчет!E26 -> 54.6347
A41: 5 | B41: =Расчет!F27 -> кв.120х3 | C41: =Расчет!F28 -> С245 | D41: =Расчет!F26 -> 66.0016
A42: 6 | B42: =Расчет!G27 -> кв.120х3 | C42: =Расчет!G28 -> С345 | D42: =Расчет!G26 -> 66.0148
A43: 7 | B43: =Расчет!H27 -> кв.100х4 | C43: =Расчет!H28 -> С245 | D43: =Расчет!H26 -> 72.0012
...

Sheet Расчет
N1: Выключатель | O1: № | P1: Сталь | Q1: Ry | S1: h | T1: b | U1: S | V1: t | W1: R | X1: А, см2 | Y1: вес, кг | Z1: Ix, см4 | AA1: Wx, см3 | AB1: Sx, см3 | AC1: ix, см | AD1: Iy, см4 | AE1: Wy, см3 | AF1: iy, см | AH1: К-т исп по гибкости | AK1: К-т исп по прочности низ | AN1: К-т исп по прочности верх | AQ1: К-т исп по прогибам низ | AT1: К-т исп по прогибам верх | AV1: Проходит? Нижний | AX1: Проходит? Верхний
AH2: 300 | AJ2: верт | AK2: =(D8*Лист1!B6+0.6*0.32*0.5)*Лист1!B7^2*Лист1!F8 -> 2.322 | AM2: верт | AN2: =(0.6*0.32*0.5)*Лист1!B7^2*Лист1!F8 -> 0.432 | AP2: верт | AQ2: =(D8*Лист1!B6+0.6*0.3*0.5) -> 0.51 | AS2: верт | AT2: =(0.6*0.3*0.5) -> 0.09 | AV2: 300 | AX2: 300
AJ3: гор | AK3: =(D9*(Лист1!B6+1.2)/2)*Лист1!B7^2*Лист1!G8 -> 4.3367761 | AM3: гор | AN3: =(D9*(Лист1!B6+1.2)/2)*Лист1!B7^2*Лист1!G8 -> 4.3367761 | AP3: гор | AQ3: =(D9*(Лист1!B6+1.2)/2) -> 0.96372802 | AS3: гор | AT3: =(F9*(Лист1!B6+1.2)/2) -> 0.57364763
O4: 1 | P4: С245 | Q4: 240 | R4: кв.50х2 | S4: 50 | T4: 50 | X4: 3.9 | Y4: 3 | Z4: 14.4 | AA4: 5.7 | AC4: 1.96 | AD4: 14.4 | AE4: 5.7 | AF4: 1.96 | AH4: =MAX($D$17*100/$AC4,$D$18*100/$AF4)/200 -> 1.5306122 | AK4: =(($AK$2+Y4*Лист1!$B$7^2*Лист1!$G$8/100)/(AA4/10^6)+$AK$3/(AE4/10^6))/1000/($Q4*IF(Лист1!$J$19="да",1/1.05,1)) -> 4.9662106 | AN4: =(($AK$2+Y4*Лист1!$B$7^2*Лист1!$G$8/100)/(AA4/10^6)+$AK$3/(AE4/10^6))/1000/($Q4*IF(Лист1!$J$19="да",1/1.05,1)) -> 4.9662106 | AQ4: =MAX((5/384*($AQ$2+$Y4/100)*$D$17^4/(2.06*10^8*$Z4/10^8))/($D$17/300)*INDEX(Лист1!$L$34:$L$38,MATCH(Лист1!$B$8,Лист1!$I$34:$I$38,0),1),(5/384*($AQ$3)*$D$17^4/(2.06*10^8*$AD4/10^8))/($D$17/200)) -> 18.274576 | AT4: =MAX((5/384*($AT$2+$Y4/100)*$D$17^4/(2.06*10^8*$Z4/10^8))/($D$17/300)*INDEX(Лист1!$L$34:$L$38,MATCH(Лист1!$B$8,Лист1!$I$34:$I$38,0),1),(5/384*($AT$3)*$D$17^4/(2.06*10^8*$AD4/10^8))/($D$17/200)) -> 10.877724 | AV4: =IF(OR(MAX(AH4,AQ4)>1,AK4>Лист1!$B$20,N4="-"),999999999,Y4*Лист1!$B$7+0.0001*O4) -> 999999999 | AX4: =IF(OR(MAX(AH4,AT4)>1,AN4>Лист1!$B$20,N4="-"),999999999,Y4*Лист1!$B$7+0.0001*O4) -> 999999999
N5: - | O5: 2 | P5: С245 | Q5: 240 | R5: кв.50х2,5 | S5: 50 | T5: 50 | X5: 4.7 | Y5: 3.6 | Z5: 17.2 | AA5: 6.8 | AC5: 1.93 | AD5: 17.2 | AE5: 6.8 | AF5: 1.93 | AH5: =MAX($D$18*100/$AC5,$D$17*100/$AF5)/200 -> 1.5544041 | AK5: =(($AK$2+Y5*Лист1!$B$7^2*Лист1!$G$8/100)/(AA5/10^6)+$AK$3/(AE5/10^6))/1000/($Q5*IF(Лист1!$J$19="да",1/1.05,1)) -> 4.1793971 | AN5: =(($AK$2+Y5*Лист1!$B$7^2*Лист1!$G$8/100)/(AA5/10^6)+$AK$3/(AE5/10^6))/1000/($Q5*IF(Лист1!$J$19="да",1/1.05,1)) -> 4.1793971 | AQ5: =MAX((5/384*($AQ$2+$Y5/100)*$D$17^4/(2.06*10^8*$Z5/10^8))/($D$17/300)*INDEX(Лист1!$L$34:$L$38,MATCH(Лист1!$B$8,Лист1!$I$34:$I$38,0),1),(5/384*($AQ$3)*$D$17^4/(2.06*10^8*$AD5/10^8))/($D$17/200)) -> 15.299645 | AT5: =MAX((5/384*($AT$2+$Y5/100)*$D$17^4/(2.06*10^8*$Z5/10^8))/($D$17/300)*INDEX(Лист1!$L$34:$L$38,MATCH(Лист1!$B$8,Лист1!$I$34:$I$38,0),1),(5/384*($AT$3)*$D$17^4/(2.06*10^8*$AD5/10^8))/($D$17/200)) -> 9.1069314 | AV5: =IF(OR(MAX(AH5,AQ5)>1,AK5>Лист1!$B$20,N5="-"),999999999,Y5*Лист1!$B$7+0.0001*O5) -> 999999999 | AX5: =IF(OR(MAX(AH5,AT5)>1,AN5>Лист1!$B$20,N5="-"),999999999,Y5*Лист1!$B$7+0.0001*O5) -> 999999999
O6: =O5+1 -> 3 | P6: С245 | Q6: 240 | R6: кв.50х3 | S6: 50 | T6: 50 | X6: 5.5 | Y6: 4.3 | Z6: 19.9 | AA6: 7.9 | AC6: 1.91 | AD6: 19.9 | AE6: 7.9 | AF6: 1.91 | AH6: =MAX($D$18*100/$AC6,$D$17*100/$AF6)/200 -> 1.5706806 | AK6: =(($AK$2+Y6*Лист1!$B$7^2*Лист1!$G$8/100)/(AA6/10^6)+$AK$3/(AE6/10^6))/1000/($Q6*IF(Лист1!$J$19="да",1/1.05,1)) -> 3.6140697 | AN6: =(($AK$2+Y6*Лист1!$B$7^2*Лист1!$G$8/100)/(AA6/10^6)+$AK$3/(AE6/10^6))/1000/($Q6*IF(Лист1!$J$19="да",1/1.05,1)) -> 3.6140697 | AQ6: =MAX((5/384*($AQ$2+$Y6/100)*$D$17^4/(2.06*10^8*$Z6/10^8))/($D$17/300)*INDEX(Лист1!$L$34:$L$38,MATCH(Лист1!$B$8,Лист1!$I$34:$I$38,0),1),(5/384*($AQ$3)*$D$17^4/(2.06*10^8*$AD6/10^8))/($D$17/200)) -> 13.223814 | AT6: =MAX((5/384*($AT$2+$Y6/100)*$D$17^4/(2.06*10^8*$Z6/10^8))/($D$17/300)*INDEX(Лист1!$L$34:$L$38,MATCH(Лист1!$B$8,Лист1!$I$34:$I$38,0),1),(5/384*($AT$3)*$D$17^4/(2.06*10^8*$AD6/10^8))/($D$17/200)) -> 7.8713176 | AV6: =IF(OR(MAX(AH6,AQ6)>1,AK6>Лист1!$B$20,N6="-"),999999999,Y6*Лист1!$B$7+0.0001*O6) -> 999999999 | AX6: =IF(OR(MAX(AH6,AT6)>1,AN6>Лист1!$B$20,N6="-"),999999999,Y6*Лист1!$B$7+0.0001*O6) -> 999999999
A7: Вертикальные нагрузки | D7: I ПС | F7: II ПС | O7: =O6+1 -> 4 | P7: С245 | Q7: 240 | R7: кв.50х4 | S7: 50 | T7: 50 | X7: 7.1 | Y7: 5.5 | Z7: 24.5 | AA7: 9.8 | AC7: 1.86 | AD7: 24.5 | AE7: 9.8 | AF7: 1.86 | AH7: =MAX($D$18*100/$AC7,$D$17*100/$AF7)/200 -> 1.6129032 | AK7: =(($AK$2+Y7*Лист1!$B$7^2*Лист1!$G$8/100)/(AA7/10^6)+$AK$3/(AE7/10^6))/1000/($Q7*IF(Лист1!$J$19="да",1/1.05,1)) -> 2.9363419 | AN7: =(($AK$2+Y7*Лист1!$B$7^2*Лист1!$G$8/100)/(AA7/10^6)+$AK$3/(AE7/10^6))/1000/($Q7*IF(Лист1!$J$19="да",1/1.05,1)) -> 2.9363419 | AQ7: =MAX((5/384*($AQ$2+$Y7/100)*$D$17^4/(2.06*10^8*$Z7/10^8))/($D$17/300)*INDEX(Лист1!$L$34:$L$38,MATCH(Лист1!$B$8,Лист1!$I$34:$I$38,0),1),(5/384*($AQ$3)*$D$17^4/(2.06*10^8*$AD7/10^8))/($D$17/200)) -> 10.740975 | AT7: =MAX((5/384*($AT$2+$Y7/100)*$D$17^4/(2.06*10^8*$Z7/10^8))/($D$17/300)*INDEX(Лист1!$L$34:$L$38,MATCH(Лист1!$B$8,Лист1!$I$34:$I$38,0),1),(5/384*($AT$3)*$D$17^4/(2.06*10^8*$AD7/10^8))/($D$17/200)) -> 6.3934375 | AV7: =IF(OR(MAX(AH7,AQ7)>1,AK7>Лист1!$B$20,N7="-"),999999999,Y7*Лист1!$B$7+0.0001*O7) -> 999999999 | AX7: =IF(OR(MAX(AH7,AT7)>1,AN7>Лист1!$B$20,N7="-"),999999999,Y7*Лист1!$B$7+0.0001*O7) -> 999999999
A8: Расчетная вертикальная нагрузка | D8: =Лист1!D17 -> 0.42 | E8: кПа | F8: =D8/1.2 -> 0.35 | M8: кПа | O8: =O7+1 -> 5 | P8: С245 | Q8: 240 | R8: кв.50х5 | S8: 50 | T8: 50 | X8: 8.6 | Y8: 6.7 | Z8: 28.3 | AA8: 11.3 | AC8: 1.81 | AD8: 28.3 | AE8: 11.3 | AF8: 1.81 | AH8: =MAX($D$18*100/$AC8,$D$17*100/$AF8)/200 -> 1.6574586 | AK8: =(($AK$2+Y8*Лист1!$B$7^2*Лист1!$G$8/100)/(AA8/10^6)+$AK$3/(AE8/10^6))/1000/($Q8*IF(Лист1!$J$19="да",1/1.05,1)) -> 2.5664735 | AN8: =(($AK$2+Y8*Лист1!$B$7^2*Лист1!$G$8/100)/(AA8/10^6)+$AK$3/(AE8/10^6))/1000/($Q8*IF(Лист1!$J$19="да",1/1.05,1)) -> 2.5664735 | AQ8: =MAX((5/384*($AQ$2+$Y8/100)*$D$17^4/(2.06*10^8*$Z8/10^8))/($D$17/300)*INDEX(Лист1!$L$34:$L$38,MATCH(Лист1!$B$8,Лист1!$I$34:$I$38,0),1),(5/384*($AQ$3)*$D$17^4/(2.06*10^8*$AD8/10^8))/($D$17/200)) -> 9.298724 | AT8: =MAX((5/384*($AT$2+$Y8/100)*$D$17^4/(2.06*10^8*$Z8/10^8))/($D$17/300)*INDEX(Лист1!$L$34:$L$38,MATCH(Лист1!$B$8,Лист1!$I$34:$I$38,0),1),(5/384*($AT$3)*$D$17^4/(2.06*10^8*$AD8/10^8))/($D$17/200)) -> 5.5349548 | AV8: =IF(OR(MAX(AH8,AQ8)>1,AK8>Лист1!$B$20,N8="-"),999999999,Y8*Лист1!$B$7+0.0001*O8) -> 999999999 | AX8: =IF(OR(MAX(AH8,AT8)>1,AN8>Лист1!$B$20,N8="-"),999999999,Y8*Лист1!$B$7+0.0001*O8) -> 999999999
A9: Расчетная горизонтальная нагрузка | D9: =IF(Лист1!J20="да",-'Ветер по СП РК EN'!D28+'Ветер по СП РК EN'!C45,'Ветер СП'!G25+'Ветер СП'!G35)*Лист1!B3 -> 0.87611638 | E9: кПа | F9: =IF(Лист1!J20="да",-'Ветер по СП РК EN'!D29/1.5+'Ветер по СП РК EN'!C45/1.5,'Ветер СП'!G26/1.4+'Ветер СП'!G35/1.4)*Лист1!B3 -> 0.52149785 | M9: кПа | N9: - | O9: =O8+1 -> 6 | P9: С245 | Q9: 240 | R9: кв.80х2,5 | S9: 80 | T9: 80 | X9: 7.7 | Y9: 6 | Z9: 74.6 | AA9: 18.7 | AC9: 3.12 | AD9: 74.6 | AE9: 18.7 | AF9: 3.12 | AH9: =MAX($D$18*100/$AC9,$D$17*100/$AF9)/200 -> 0.96153846 | AK9: =(($AK$2+Y9*Лист1!$B$7^2*Лист1!$G$8/100)/(AA9/10^6)+$AK$3/(AE9/10^6))/1000/($Q9*IF(Лист1!$J$19="да",1/1.05,1)) -> 1.5438449 | AN9: =(($AK$2+Y9*Лист1!$B$7^2*Лист1!$G$8/100)/(AA9/10^6)+$AK$3/(AE9/10^6))/1000/($Q9*IF(Лист1!$J$19="да",1/1.05,1)) -> 1.5438449 | AQ9: =MAX((5/384*($AQ$2+$Y9/100)*$D$17^4/(2.06*10^8*$Z9/10^8))/($D$17/300)*INDEX(Лист1!$L$34:$L$38,MATCH(Лист1!$B$8,Лист1!$I$34:$I$38,0),1),(5/384*($AQ$3)*$D$17^4/(2.06*10^8*$AD9/10^8))/($D$17/200)) -> 3.527532 | AT9: =MAX((5/384*($AT$2+$Y9/100)*$D$17^4/(2.06*10^8*$Z9/10^8))/($D$17/300)*INDEX(Лист1!$L$34:$L$38,MATCH(Лист1!$B$8,Лист1!$I$34:$I$38,0),1),(5/384*($AT$3)*$D$17^4/(2.06*10^8*$AD9/10^8))/($D$17/200)) -> 2.0997214 | AV9: =IF(OR(MAX(AH9,AQ9)>1,AK9>Лист1!$B$20,N9="-"),999999999,Y9*Лист1!$B$7+0.0001*O9) -> 999999999 | AX9: =IF(OR(MAX(AH9,AT9)>1,AN9>Лист1!$B$20,N9="-"),999999999,Y9*Лист1!$B$7+0.0001*O9) -> 999999999
O10: =O9+1 -> 7 | P10: С245 | Q10: 240 | R10: кв.80х3 | S10: 80 | T10: 80 | X10: 9.2 | Y10: 7.2 | Z10: 89.5 | AA10: 22.4 | AC10: 3.12 | AD10: 89.5 | AE10: 22.4 | AF10: 3.12 | AH10: =MAX($D$18*100/$AC10,$D$17*100/$AF10)/200 -> 0.96153846 | AK10: =(($AK$2+Y10*Лист1!$B$7^2*Лист1!$G$8/100)/(AA10/10^6)+$AK$3/(AE10/10^6))/1000/($Q10*IF(Лист1!$J$19="да",1/1.05,1)) -> 1.2988795 | AN10: =(($AK$2+Y10*Лист1!$B$7^2*Лист1!$G$8/100)/(AA10/10^6)+$AK$3/(AE10/10^6))/1000/($Q10*IF(Лист1!$J$19="да",1/1.05,1)) -> 1.2988795 | AQ10: =MAX((5/384*($AQ$2+$Y10/100)*$D$17^4/(2.06*10^8*$Z10/10^8))/($D$17/300)*INDEX(Лист1!$L$34:$L$38,MATCH(Лист1!$B$8,Лист1!$I$34:$I$38,0),1),(5/384*($AQ$3)*$D$17^4/(2.06*10^8*$AD10/10^8))/($D$17/200)) -> 2.9402669 | AT10: =MAX((5/384*($AT$2+$Y10/100)*$D$17^4/(2.06*10^8*$Z10/10^8))/($D$17/300)*INDEX(Лист1!$L$34:$L$38,MATCH(Лист1!$B$8,Лист1!$I$34:$I$38,0),1),(5/384*($AT$3)*$D$17^4/(2.06*10^8*$AD10/10^8))/($D$17/200)) -> 1.7501589 | AV10: =IF(OR(MAX(AH10,AQ10)>1,AK10>Лист1!$B$20,N10="-"),999999999,Y10*Лист1!$B$7+0.0001*O10) -> 999999999 | AX10: =IF(OR(MAX(AH10,AT10)>1,AN10>Лист1!$B$20,N10="-"),999999999,Y10*Лист1!$B$7+0.0001*O10) -> 999999999
O11: =O10+1 -> 8 | P11: С245 | Q11: 240 | R11: кв.80х4 | S11: 80 | T11: 80 | X11: 12.2 | Y11: 9.6 | Z11: 115.3 | AA11: 28.8 | AC11: 3.07 | AD11: 115.3 | AE11: 28.8 | AF11: 3.07 | AH11: =MAX($D$18*100/$AC11,$D$17*100/$AF11)/200 -> 0.9771987 | AK11: =(($AK$2+Y11*Лист1!$B$7^2*Лист1!$G$8/100)/(AA11/10^6)+$AK$3/(AE11/10^6))/1000/($Q11*IF(Лист1!$J$19="да",1/1.05,1)) -> 1.0258646 | AN11: =(($AK$2+Y11*Лист1!$B$7^2*Лист1!$G$8/100)/(AA11/10^6)+$AK$3/(AE11/10^6))/1000/($Q11*IF(Лист1!$J$19="да",1/1.05,1)) -> 1.0258646 | AQ11: =MAX((5/384*($AQ$2+$Y11/100)*$D$17^4/(2.06*10^8*$Z11/10^8))/($D$17/300)*INDEX(Лист1!$L$34:$L$38,MATCH(Лист1!$B$8,Лист1!$I$34:$I$38,0),1),(5/384*($AQ$3)*$D$17^4/(2.06*10^8*$AD11/10^8))/($D$17/200)) -> 2.2823408 | AT11: =MAX((5/384*($AT$2+$Y11/100)*$D$17^4/(2.06*10^8*$Z11/10^8))/($D$17/300)*INDEX(Лист1!$L$34:$L$38,MATCH(Лист1!$B$8,Лист1!$I$34:$I$38,0),1),(5/384*($AT$3)*$D$17^4/(2.06*10^8*$AD11/10^8))/($D$17/200)) -> 1.3585362 | AV11: =IF(OR(MAX(AH11,AQ11)>1,AK11>Лист1!$B$20,N11="-"),999999999,Y11*Лист1!$B$7+0.0001*O11) -> 999999999 | AX11: =IF(OR(MAX(AH11,AT11)>1,AN11>Лист1!$B$20,N11="-"),999999999,Y11*Лист1!$B$7+0.0001*O11) -> 999999999
O12: =O11+1 -> 9 | P12: С245 | Q12: 240 | R12: кв.80х5 | S12: 80 | T12: 80 | X12: 15 | Y12: 11.8 | Z12: 138 | AA12: 34.5 | AC12: 3.03 | AD12: 138 | AE12: 34.5 | AF12: 3.03 | AH12: =MAX($D$18*100/$AC12,$D$17*100/$AF12)/200 -> 0.99009901 | AK12: =(($AK$2+Y12*Лист1!$B$7^2*Лист1!$G$8/100)/(AA12/10^6)+$AK$3/(AE12/10^6))/1000/($Q12*IF(Лист1!$J$19="да",1/1.05,1)) -> 0.86833045 | AN12: =(($AK$2+Y12*Лист1!$B$7^2*Лист1!$G$8/100)/(AA12/10^6)+$AK$3/(AE12/10^6))/1000/($Q12*IF(Лист1!$J$19="да",1/1.05,1)) -> 0.86833045 | AQ12: =MAX((5/384*($AQ$2+$Y12/100)*$D$17^4/(2.06*10^8*$Z12/10^8))/($D$17/300)*INDEX(Лист1!$L$34:$L$38,MATCH(Лист1!$B$8,Лист1!$I$34:$I$38,0),1),(5/384*($AQ$3)*$D$17^4/(2.06*10^8*$AD12/10^8))/($D$17/200)) -> 1.9069122 | AT12: =MAX((5/384*($AT$2+$Y12/100)*$D$17^4/(2.06*10^8*$Z12/10^8))/($D$17/300)*INDEX(Лист1!$L$34:$L$38,MATCH(Лист1!$B$8,Лист1!$I$34:$I$38,0),1),(5/384*($AT$3)*$D$17^4/(2.06*10^8*$AD12/10^8))/($D$17/200)) -> 1.1350668 | AV12: =IF(OR(MAX(AH12,AQ12)>1,AK12>Лист1!$B$20,N12="-"),999999999,Y12*Лист1!$B$7+0.0001*O12) -> 999999999 | AX12: =IF(OR(MAX(AH12,AT12)>1,AN12>Лист1!$B$20,N12="-"),999999999,Y12*Лист1!$B$7+0.0001*O12) -> 999999999
O13: =O12+1 -> 10 | P13: С245 | Q13: 240 | R13: кв.80х6 | S13: 80 | T13: 80 | X13: 17.8 | Y13: 14 | Z13: 158.1 | AA13: 39.5 | AC13: 2.98 | AD13: 158.1 | AE13: 39.5 | AF13: 2.98 | AH13: =MAX($D$18*100/$AC13,$D$17*100/$AF13)/200 -> 1.0067114 | AK13: =(($AK$2+Y13*Лист1!$B$7^2*Лист1!$G$8/100)/(AA13/10^6)+$AK$3/(AE13/10^6))/1000/($Q13*IF(Лист1!$J$19="да",1/1.05,1)) -> 0.76885824 | AN13: =(($AK$2+Y13*Лист1!$B$7^2*Лист1!$G$8/100)/(AA13/10^6)+$AK$3/(AE13/10^6))/1000/($Q13*IF(Лист1!$J$19="да",1/1.05,1)) -> 0.76885824 | AQ13: =MAX((5/384*($AQ$2+$Y13/100)*$D$17^4/(2.06*10^8*$Z13/10^8))/($D$17/300)*INDEX(Лист1!$L$34:$L$38,MATCH(Лист1!$B$8,Лист1!$I$34:$I$38,0),1),(5/384*($AQ$3)*$D$17^4/(2.06*10^8*$AD13/10^8))/($D$17/200)) -> 1.6839456 | AT13: =MAX((5/384*($AT$2+$Y13/100)*$D$17^4/(2.06*10^8*$Z13/10^8))/($D$17/300)*INDEX(Лист1!$L$34:$L$38,MATCH(Лист1!$B$8,Лист1!$I$34:$I$38,0),1),(5/384*($AT$3)*$D$17^4/(2.06*10^8*$AD13/10^8))/($D$17/200)) -> 0.9907604 | AV13: =IF(OR(MAX(AH13,AQ13)>1,AK13>Лист1!$B$20,N13="-"),999999999,Y13*Лист1!$B$7+0.0001*O13) -> 999999999 | AX13: =IF(OR(MAX(AH13,AT13)>1,AN13>Лист1!$B$20,N13="-"),999999999,Y13*Лист1!$B$7+0.0001*O13) -> 999999999
O14: =O13+1 -> 11 | P14: С245 | Q14: 240 | R14: кв.100х3 | S14: 100 | T14: 100 | X14: 11.6 | Y14: 9.1 | Z14: 180.2 | AA14: 36 | AC14: 3.94 | AD14: 180.2 | AE14: 36 | AF14: 3.94 | AH14: =MAX($D$18*100/$AC14,$D$17*100/$AF14)/200 -> 0.76142132 | AK14: =(($AK$2+Y14*Лист1!$B$7^2*Лист1!$G$8/100)/(AA14/10^6)+$AK$3/(AE14/10^6))/1000/($Q14*IF(Лист1!$J$19="да",1/1.05,1)) -> 0.81808751 | AN14: =(($AK$2+Y14*Лист1!$B$7^2*Лист1!$G$8/100)/(AA14/10^6)+$AK$3/(AE14/10^6))/1000/($Q14*IF(Лист1!$J$19="да",1/1.05,1)) -> 0.81808751 | AQ14: =MAX((5/384*($AQ$2+$Y14/100)*$D$17^4/(2.06*10^8*$Z14/10^8))/($D$17/300)*INDEX(Лист1!$L$34:$L$38,MATCH(Лист1!$B$8,Лист1!$I$34:$I$38,0),1),(5/384*($AQ$3)*$D$17^4/(2.06*10^8*$AD14/10^8))/($D$17/200)) -> 1.4603434 | AT14: =MAX((5/384*($AT$2+$Y14/100)*$D$17^4/(2.06*10^8*$Z14/10^8))/($D$17/300)*INDEX(Лист1!$L$34:$L$38,MATCH(Лист1!$B$8,Лист1!$I$34:$I$38,0),1),(5/384*($AT$3)*$D$17^4/(2.06*10^8*$AD14/10^8))/($D$17/200)) -> 0.86925205 | AV14: =IF(OR(MAX(AH14,AQ14)>1,AK14>Лист1!$B$20,N14="-"),999999999,Y14*Лист1!$B$7+0.0001*O14) -> 999999999 | AX14: =IF(OR(MAX(AH14,AT14)>1,AN14>Лист1!$B$20,N14="-"),999999999,Y14*Лист1!$B$7+0.0001*O14) -> 54.6011
O15: =O14+1 -> 12 | P15: С245 | Q15: 240 | R15: кв.100х4 | S15: 100 | T15: 100 | X15: 15.3 | Y15: 12 | Z15: 231.3 | AA15: 46.3 | AC15: 3.89 | AD15: 231.3 | AE15: 46.3 | AF15: 3.89 | AH15: =MAX($D$18*100/$AC15,$D$17*100/$AF15)/200 -> 0.77120823 | AK15: =(($AK$2+Y15*Лист1!$B$7^2*Лист1!$G$8/100)/(AA15/10^6)+$AK$3/(AE15/10^6))/1000/($Q15*IF(Лист1!$J$19="да",1/1.05,1)) -> 0.64783802 | AN15: =(($AK$2+Y15*Лист1!$B$7^2*Лист1!$G$8/100)/(AA15/10^6)+$AK$3/(AE15/10^6))/1000/($Q15*IF(Лист1!$J$19="да",1/1.05,1)) -> 0.64783802 | AQ15: =MAX((5/384*($AQ$2+$Y15/100)*$D$17^4/(2.06*10^8*$Z15/10^8))/($D$17/300)*INDEX(Лист1!$L$34:$L$38,MATCH(Лист1!$B$8,Лист1!$I$34:$I$38,0),1),(5/384*($AQ$3)*$D$17^4/(2.06*10^8*$AD15/10^8))/($D$17/200)) -> 1.1377168 | AT15: =MAX((5/384*($AT$2+$Y15/100)*$D$17^4/(2.06*10^8*$Z15/10^8))/($D$17/300)*INDEX(Лист1!$L$34:$L$38,MATCH(Лист1!$B$8,Лист1!$I$34:$I$38,0),1),(5/384*($AT$3)*$D$17^4/(2.06*10^8*$AD15/10^8))/($D$17/200)) -> 0.67721236 | AV15: =IF(OR(MAX(AH15,AQ15)>1,AK15>Лист1!$B$20,N15="-"),999999999,Y15*Лист1!$B$7+0.0001*O15) -> 999999999 | AX15: =IF(OR(MAX(AH15,AT15)>1,AN15>Лист1!$B$20,N15="-"),999999999,Y15*Лист1!$B$7+0.0001*O15) -> 72.0012
O16: =O15+1 -> 13 | P16: С245 | Q16: 240 | R16: кв.100х5 | S16: 100 | T16: 100 | X16: 18.9 | Y16: 14.8 | Z16: 278.7 | AA16: 55.7 | AC16: 3.84 | AD16: 278.7 | AE16: 55.7 | AF16: 3.84 | AH16: =MAX($D$18*100/$AC16,$D$17*100/$AF16)/200 -> 0.78125 | AK16: =(($AK$2+Y16*Лист1!$B$7^2*Лист1!$G$8/100)/(AA16/10^6)+$AK$3/(AE16/10^6))/1000/($Q16*IF(Лист1!$J$19="да",1/1.05,1)) -> 0.54793358 | AN16: =(($AK$2+Y16*Лист1!$B$7^2*Лист1!$G$8/100)/(AA16/10^6)+$AK$3/(AE16/10^6))/1000/($Q16*IF(Лист1!$J$19="да",1/1.05,1)) -> 0.54793358 | AQ16: =MAX((5/384*($AQ$2+$Y16/100)*$D$17^4/(2.06*10^8*$Z16/10^8))/($D$17/300)*INDEX(Лист1!$L$34:$L$38,MATCH(Лист1!$B$8,Лист1!$I$34:$I$38,0),1),(5/384*($AQ$3)*$D$17^4/(2.06*10^8*$AD16/10^8))/($D$17/200)) -> 0.96702008 | AT16: =MAX((5/384*($AT$2+$Y16/100)*$D$17^4/(2.06*10^8*$Z16/10^8))/($D$17/300)*INDEX(Лист1!$L$34:$L$38,MATCH(Лист1!$B$8,Лист1!$I$34:$I$38,0),1),(5/384*($AT$3)*$D$17^4/(2.06*10^8*$AD16/10^8))/($D$17/200)) -> 0.56203523 | AV16: =IF(OR(MAX(AH16,AQ16)>1,AK16>Лист1!$B$20,N16="-"),999999999,Y16*Лист1!$B$7+0.0001*O16) -> 88.8013 | AX16: =IF(OR(MAX(AH16,AT16)>1,AN16>Лист1!$B$20,N16="-"),999999999,Y16*Лист1!$B$7+0.0001*O16) -> 88.8013
A17: расчетная длина | C17: из плоскости | D17: =Лист1!B7 -> 6 | E17: м | O17: =O16+1 -> 14 | P17: С245 | Q17: 240 | R17: кв.100х6 | S17: 100 | T17: 100 | X17: 22.6 | Y17: 17.7 | Z17: 326.3 | AA17: 65.3 | AC17: 3.8 | AD17: 326.3 | AE17: 65.3 | AF17: 3.8 | AH17: =MAX($D$18*100/$AC17,$D$17*100/$AF17)/200 -> 0.78947368 | AK17: =(($AK$2+Y17*Лист1!$B$7^2*Лист1!$G$8/100)/(AA17/10^6)+$AK$3/(AE17/10^6))/1000/($Q17*IF(Лист1!$J$19="да",1/1.05,1)) -> 0.47570674 | AN17: =(($AK$2+Y17*Лист1!$B$7^2*Лист1!$G$8/100)/(AA17/10^6)+$AK$3/(AE17/10^6))/1000/($Q17*IF(Лист1!$J$19="да",1/1.05,1)) -> 0.47570674 | AQ17: =MAX((5/384*($AQ$2+$Y17/100)*$D$17^4/(2.06*10^8*$Z17/10^8))/($D$17/300)*INDEX(Лист1!$L$34:$L$38,MATCH(Лист1!$B$8,Лист1!$I$34:$I$38,0),1),(5/384*($AQ$3)*$D$17^4/(2.06*10^8*$AD17/10^8))/($D$17/200)) -> 0.86235528 | AT17: =MAX((5/384*($AT$2+$Y17/100)*$D$17^4/(2.06*10^8*$Z17/10^8))/($D$17/300)*INDEX(Лист1!$L$34:$L$38,MATCH(Лист1!$B$8,Лист1!$I$34:$I$38,0),1),(5/384*($AT$3)*$D$17^4/(2.06*10^8*$AD17/10^8))/($D$17/200)) -> 0.48004664 | AV17: =IF(OR(MAX(AH17,AQ17)>1,AK17>Лист1!$B$20,N17="-"),999999999,Y17*Лист1!$B$7+0.0001*O17) -> 106.2014 | AX17: =IF(OR(MAX(AH17,AT17)>1,AN17>Лист1!$B$20,N17="-"),999999999,Y17*Лист1!$B$7+0.0001*O17) -> 106.2014
C18: в плоскости | D18: =Лист1!B7*INDEX(Лист1!K34:K38,MATCH(Лист1!B8,Лист1!I34:I38,0),1) -> 6 | E18: м | O18: =O17+1 -> 15 | P18: С245 | Q18: 240 | R18: кв.100х7 | S18: 100 | T18: 100 | X18: 26.2 | Y18: 20.5 | Z18: 373.9 | AA18: 74.8 | AC18: 3.75 | AD18: 373.9 | AE18: 74.8 | AF18: 3.75 | AH18: =MAX($D$18*100/$AC18,$D$17*100/$AF18)/200 -> 0.8 | AK18: =(($AK$2+Y18*Лист1!$B$7^2*Лист1!$G$8/100)/(AA18/10^6)+$AK$3/(AE18/10^6))/1000/($Q18*IF(Лист1!$J$19="да",1/1.05,1)) -> 0.42230816 | AN18: =(($AK$2+Y18*Лист1!$B$7^2*Лист1!$G$8/100)/(AA18/10^6)+$AK$3/(AE18/10^6))/1000/($Q18*IF(Лист1!$J$19="да",1/1.05,1)) -> 0.42230816 | AQ18: =MAX((5/384*($AQ$2+$Y18/100)*$D$17^4/(2.06*10^8*$Z18/10^8))/($D$17/300)*INDEX(Лист1!$L$34:$L$38,MATCH(Лист1!$B$8,Лист1!$I$34:$I$38,0),1),(5/384*($AQ$3)*$D$17^4/(2.06*10^8*$AD18/10^8))/($D$17/200)) -> 0.78324412 | AT18: =MAX((5/384*($AT$2+$Y18/100)*$D$17^4/(2.06*10^8*$Z18/10^8))/($D$17/300)*INDEX(Лист1!$L$34:$L$38,MATCH(Лист1!$B$8,Лист1!$I$34:$I$38,0),1),(5/384*($AT$3)*$D$17^4/(2.06*10^8*$AD18/10^8))/($D$17/200)) -> 0.41893346 | AV18: =IF(OR(MAX(AH18,AQ18)>1,AK18>Лист1!$B$20,N18="-"),999999999,Y18*Лист1!$B$7+0.0001*O18) -> 123.0015 | AX18: =IF(OR(MAX(AH18,AT18)>1,AN18>Лист1!$B$20,N18="-"),999999999,Y18*Лист1!$B$7+0.0001*O18) -> 123.0015
O19: =O18+1 -> 16 | P19: С245 | Q19: 240 | R19: кв.120х3 | S19: 120 | T19: 120 | X19: 14 | Y19: 11 | Z19: 315.1 | AA19: 52.5 | AC19: 4.76 | AD19: 315.1 | AE19: 52.5 | AF19: 4.76 | AH19: =MAX($D$18*100/$AC19,$D$17*100/$AF19)/200 -> 0.6302521 | AK19: =(($AK$2+Y19*Лист1!$B$7^2*Лист1!$G$8/100)/(AA19/10^6)+$AK$3/(AE19/10^6))/1000/($Q19*IF(Лист1!$J$19="да",1/1.05,1)) -> 0.56776001 | AN19: =(($AK$2+Y19*Лист1!$B$7^2*Лист1!$G$8/100)/(AA19/10^6)+$AK$3/(AE19/10^6))/1000/($Q19*IF(Лист1!$J$19="да",1/1.05,1)) -> 0.56776001 | AQ19: =MAX((5/384*($AQ$2+$Y19/100)*$D$17^4/(2.06*10^8*$Z19/10^8))/($D$17/300)*INDEX(Лист1!$L$34:$L$38,MATCH(Лист1!$B$8,Лист1!$I$34:$I$38,0),1),(5/384*($AQ$3)*$D$17^4/(2.06*10^8*$AD19/10^8))/($D$17/200)) -> 0.83514405 | AT19: =MAX((5/384*($AT$2+$Y19/100)*$D$17^4/(2.06*10^8*$Z19/10^8))/($D$17/300)*INDEX(Лист1!$L$34:$L$38,MATCH(Лист1!$B$8,Лист1!$I$34:$I$38,0),1),(5/384*($AT$3)*$D$17^4/(2.06*10^8*$AD19/10^8))/($D$17/200)) -> 0.49710955 | AV19: =IF(OR(MAX(AH19,AQ19)>1,AK19>Лист1!$B$20,N19="-"),999999999,Y19*Лист1!$B$7+0.0001*O19) -> 66.0016 | AX19: =IF(OR(MAX(AH19,AT19)>1,AN19>Лист1!$B$20,N19="-"),999999999,Y19*Лист1!$B$7+0.0001*O19) -> 66.0016
B20: 1 | C20: 2 | D20: 3 | E20: 4 | F20: 5 | G20: 6 | H20: 7 | I20: 8 | J20: 9 | K20: 10 | O20: =O19+1 -> 17 | P20: С245 | Q20: 240 | R20: кв.120х4 | S20: 120 | T20: 120 | X20: 18.5 | Y20: 14.5 | Z20: 408.5 | AA20: 68.1 | AC20: 4.71 | AD20: 408.5 | AE20: 68.1 | AF20: 4.71 | AH20: =MAX($D$18*100/$AC20,$D$17*100/$AF20)/200 -> 0.63694268 | AK20: =(($AK$2+Y20*Лист1!$B$7^2*Лист1!$G$8/100)/(AA20/10^6)+$AK$3/(AE20/10^6))/1000/($Q20*IF(Лист1!$J$19="да",1/1.05,1)) -> 0.44733701 | AN20: =(($AK$2+Y20*Лист1!$B$7^2*Лист1!$G$8/100)/(AA20/10^6)+$AK$3/(AE20/10^6))/1000/($Q20*IF(Лист1!$J$19="да",1/1.05,1)) -> 0.44733701 | AQ20: =MAX((5/384*($AQ$2+$Y20/100)*$D$17^4/(2.06*10^8*$Z20/10^8))/($D$17/300)*INDEX(Лист1!$L$34:$L$38,MATCH(Лист1!$B$8,Лист1!$I$34:$I$38,0),1),(5/384*($AQ$3)*$D$17^4/(2.06*10^8*$AD20/10^8))/($D$17/200)) -> 0.65674353 | AT20: =MAX((5/384*($AT$2+$Y20/100)*$D$17^4/(2.06*10^8*$Z20/10^8))/($D$17/300)*INDEX(Лист1!$L$34:$L$38,MATCH(Лист1!$B$8,Лист1!$I$34:$I$38,0),1),(5/384*($AT$3)*$D$17^4/(2.06*10^8*$AD20/10^8))/($D$17/200)) -> 0.38344974 | AV20: =IF(OR(MAX(AH20,AQ20)>1,AK20>Лист1!$B$20,N20="-"),999999999,Y20*Лист1!$B$7+0.0001*O20) -> 87.0017 | AX20: =IF(OR(MAX(AH20,AT20)>1,AN20>Лист1!$B$20,N20="-"),999999999,Y20*Лист1!$B$7+0.0001*O20) -> 87.0017
A21: Подбор | B21: =SMALL($AV$4:$AV$413,B20) -> 66.0016 | C21: =SMALL($AV$4:$AV$413,C20) -> 66.0148 | D21: =SMALL($AV$4:$AV$413,D20) -> 87.0017 | E21: =SMALL($AV$4:$AV$413,E20) -> 87.0078 | F21: =SMALL($AV$4:$AV$413,F20) -> 87.0149 | G21: =SMALL($AV$4:$AV$413,G20) -> 87.021 | H21: =SMALL($AV$4:$AV$413,H20) -> 87.0283 | I21: =SMALL($AV$4:$AV$413,I20) -> 87.0356 | ... K21: =SMALL($AV$4:$AV$413,K20) -> 88.8145 | O21: =O20+1 -> 18 | P21: С245 | Q21: 240 | R21: кв.120х5 | S21: 120 | T21: 120 | X21: 22.9 | Y21: 18 | Z21: 497.9 | AA21: 83 | AC21: 4.66 | AD21: 497.9 | AE21: 83 | AF21: 4.66 | AH21: =MAX($D$18*100/$AC21,$D$17*100/$AF21)/200 -> 0.64377682 | AK21: =(($AK$2+Y21*Лист1!$B$7^2*Лист1!$G$8/100)/(AA21/10^6)+$AK$3/(AE21/10^6))/1000/($Q21*IF(Лист1!$J$19="да",1/1.05,1)) -> 0.37493856 | AN21: =(($AK$2+Y21*Лист1!$B$7^2*Лист1!$G$8/100)/(AA21/10^6)+$AK$3/(AE21/10^6))/1000/($Q21*IF(Лист1!$J$19="да",1/1.05,1)) -> 0.37493856 | AQ21: =MAX((5/384*($AQ$2+$Y21/100)*$D$17^4/(2.06*10^8*$Z21/10^8))/($D$17/300)*INDEX(Лист1!$L$34:$L$38,MATCH(Лист1!$B$8,Лист1!$I$34:$I$38,0),1),(5/384*($AQ$3)*$D$17^4/(2.06*10^8*$AD21/10^8))/($D$17/200)) -> 0.56761456 | AT21: =MAX((5/384*($AT$2+$Y21/100)*$D$17^4/(2.06*10^8*$Z21/10^8))/($D$17/300)*INDEX(Лист1!$L$34:$L$38,MATCH(Лист1!$B$8,Лист1!$I$34:$I$38,0),1),(5/384*($AT$3)*$D$17^4/(2.06*10^8*$AD21/10^8))/($D$17/200)) -> 0.31459976 | AV21: =IF(OR(MAX(AH21,AQ21)>1,AK21>Лист1!$B$20,N21="-"),999999999,Y21*Лист1!$B$7+0.0001*O21) -> 108.0018 | AX21: =IF(OR(MAX(AH21,AT21)>1,AN21>Лист1!$B$20,N21="-"),999999999,Y21*Лист1!$B$7+0.0001*O21) -> 108.0018
A22: сечение | B22: =INDEX($R$4:$R$413,MATCH(B21,$AV$4:$AV$413,0),1) -> кв.120х3 | C22: =INDEX($R$4:$R$413,MATCH(C21,$AV$4:$AV$413,0),1) -> кв.120х3 | D22: =INDEX($R$4:$R$413,MATCH(D21,$AV$4:$AV$413,0),1) -> кв.120х4 | E22: =INDEX($R$4:$R$413,MATCH(E21,$AV$4:$AV$413,0),1) -> пр.140х100х4 | F22: =INDEX($R$4:$R$413,MATCH(F21,$AV$4:$AV$413,0),1) -> кв.120х4 | G22: =INDEX($R$4:$R$413,MATCH(G21,$AV$4:$AV$413,0),1) -> пр.140х100х4 | H22: =INDEX($R$4:$R$413,MATCH(H21,$AV$4:$AV$413,0),1) -> пр.140х100х4 90° | I22: =INDEX($R$4:$R$413,MATCH(I21,$AV$4:$AV$413,0),1) -> пр.140х100х4 90° | ... K22: =INDEX($R$4:$R$413,MATCH(K21,$AV$4:$AV$413,0),1) -> кв.100х5 | O22: =O21+1 -> 19 | P22: С245 | Q22: 240 | R22: кв.120х6 | S22: 120 | T22: 120 | X22: 27.4 | Y22: 21.5 | Z22: 583.4 | AA22: 97.2 | AC22: 4.61 | AD22: 583.4 | AE22: 97.2 | AF22: 4.61 | AH22: =MAX($D$18*100/$AC22,$D$17*100/$AF22)/200 -> 0.65075922 | AK22: =(($AK$2+Y22*Лист1!$B$7^2*Лист1!$G$8/100)/(AA22/10^6)+$AK$3/(AE22/10^6))/1000/($Q22*IF(Лист1!$J$19="да",1/1.05,1)) -> 0.32691513 | AN22: =(($AK$2+Y22*Лист1!$B$7^2*Лист1!$G$8/100)/(AA22/10^6)+$AK$3/(AE22/10^6))/1000/($Q22*IF(Лист1!$J$19="да",1/1.05,1)) -> 0.32691513 | AQ22: =MAX((5/384*($AQ$2+$Y22/100)*$D$17^4/(2.06*10^8*$Z22/10^8))/($D$17/300)*INDEX(Лист1!$L$34:$L$38,MATCH(Лист1!$B$8,Лист1!$I$34:$I$38,0),1),(5/384*($AQ$3)*$D$17^4/(2.06*10^8*$AD22/10^8))/($D$17/200)) -> 0.50900043 | AT22: =MAX((5/384*($AT$2+$Y22/100)*$D$17^4/(2.06*10^8*$Z22/10^8))/($D$17/300)*INDEX(Лист1!$L$34:$L$38,MATCH(Лист1!$B$8,Лист1!$I$34:$I$38,0),1),(5/384*($AT$3)*$D$17^4/(2.06*10^8*$AD22/10^8))/($D$17/200)) -> 0.26849369 | AV22: =IF(OR(MAX(AH22,AQ22)>1,AK22>Лист1!$B$20,N22="-"),999999999,Y22*Лист1!$B$7+0.0001*O22) -> 129.0019 | AX22: =IF(OR(MAX(AH22,AT22)>1,AN22>Лист1!$B$20,N22="-"),999999999,Y22*Лист1!$B$7+0.0001*O22) -> 129.0019
A23: сталь | B23: =INDEX($P$4:$P$413,MATCH(B21,$AV$4:$AV$413,0),1) -> С245 | C23: =INDEX($P$4:$P$413,MATCH(C21,$AV$4:$AV$413,0),1) -> С345 | D23: =INDEX($P$4:$P$413,MATCH(D21,$AV$4:$AV$413,0),1) -> С245 | E23: =INDEX($P$4:$P$413,MATCH(E21,$AV$4:$AV$413,0),1) -> С245 | F23: =INDEX($P$4:$P$413,MATCH(F21,$AV$4:$AV$413,0),1) -> С345 | G23: =INDEX($P$4:$P$413,MATCH(G21,$AV$4:$AV$413,0),1) -> С345 | H23: =INDEX($P$4:$P$413,MATCH(H21,$AV$4:$AV$413,0),1) -> С245 | I23: =INDEX($P$4:$P$413,MATCH(I21,$AV$4:$AV$413,0),1) -> С345 | ... K23: =INDEX($P$4:$P$413,MATCH(K21,$AV$4:$AV$413,0),1) -> С345 | O23: =O22+1 -> 20 | P23: С245 | Q23: 240 | R23: кв.140х4 | S23: 140 | T23: 140 | X23: 21.6 | Y23: 17 | Z23: 657.9 | AA23: 94 | AC23: 5.52 | AD23: 657.9 | AE23: 94 | AF23: 5.52 | AH23: =MAX($D$18*100/$AC23,$D$17*100/$AF23)/200 -> 0.54347826 | AK23: =(($AK$2+Y23*Лист1!$B$7^2*Лист1!$G$8/100)/(AA23/10^6)+$AK$3/(AE23/10^6))/1000/($Q23*IF(Лист1!$J$19="да",1/1.05,1)) -> 0.32906809 | AN23: =(($AK$2+Y23*Лист1!$B$7^2*Лист1!$G$8/100)/(AA23/10^6)+$AK$3/(AE23/10^6))/1000/($Q23*IF(Лист1!$J$19="да",1/1.05,1)) -> 0.32906809 | AQ23: =MAX((5/384*($AQ$2+$Y23/100)*$D$17^4/(2.06*10^8*$Z23/10^8))/($D$17/300)*INDEX(Лист1!$L$34:$L$38,MATCH(Лист1!$B$8,Лист1!$I$34:$I$38,0),1),(5/384*($AQ$3)*$D$17^4/(2.06*10^8*$AD23/10^8))/($D$17/200)) -> 0.42334613 | AT23: =MAX((5/384*($AT$2+$Y23/100)*$D$17^4/(2.06*10^8*$Z23/10^8))/($D$17/300)*INDEX(Лист1!$L$34:$L$38,MATCH(Лист1!$B$8,Лист1!$I$34:$I$38,0),1),(5/384*($AT$3)*$D$17^4/(2.06*10^8*$AD23/10^8))/($D$17/200)) -> 0.23808971 | AV23: =IF(OR(MAX(AH23,AQ23)>1,AK23>Лист1!$B$20,N23="-"),999999999,Y23*Лист1!$B$7+0.0001*O23) -> 102.002 | AX23: =IF(OR(MAX(AH23,AT23)>1,AN23>Лист1!$B$20,N23="-"),999999999,Y23*Лист1!$B$7+0.0001*O23) -> 102.002
O24: =O23+1 -> 21 | P24: С245 | Q24: 240 | R24: кв.140х5 | S24: 140 | T24: 140 | X24: 26.9 | Y24: 21.1 | Z24: 808.4 | AA24: 115.5 | AC24: 5.48 | AD24: 808.4 | AE24: 115.5 | AF24: 5.48 | AH24: =MAX($D$18*100/$AC24,$D$17*100/$AF24)/200 -> 0.54744526 | AK24: =(($AK$2+Y24*Лист1!$B$7^2*Лист1!$G$8/100)/(AA24/10^6)+$AK$3/(AE24/10^6))/1000/($Q24*IF(Лист1!$J$19="да",1/1.05,1)) -> 0.27446883 | AN24: =(($AK$2+Y24*Лист1!$B$7^2*Лист1!$G$8/100)/(AA24/10^6)+$AK$3/(AE24/10^6))/1000/($Q24*IF(Лист1!$J$19="да",1/1.05,1)) -> 0.27446883 | AQ24: =MAX((5/384*($AQ$2+$Y24/100)*$D$17^4/(2.06*10^8*$Z24/10^8))/($D$17/300)*INDEX(Лист1!$L$34:$L$38,MATCH(Лист1!$B$8,Лист1!$I$34:$I$38,0),1),(5/384*($AQ$3)*$D$17^4/(2.06*10^8*$AD24/10^8))/($D$17/200)) -> 0.36530492 | AT24: =MAX((5/384*($AT$2+$Y24/100)*$D$17^4/(2.06*10^8*$Z24/10^8))/($D$17/300)*INDEX(Лист1!$L$34:$L$38,MATCH(Лист1!$B$8,Лист1!$I$34:$I$38,0),1),(5/384*($AT$3)*$D$17^4/(2.06*10^8*$AD24/10^8))/($D$17/200)) -> 0.1937645 | AV24: =IF(OR(MAX(AH24,AQ24)>1,AK24>Лист1!$B$20,N24="-"),999999999,Y24*Лист1!$B$7+0.0001*O24) -> 126.6021 | AX24: =IF(OR(MAX(AH24,AT24)>1,AN24>Лист1!$B$20,N24="-"),999999999,Y24*Лист1!$B$7+0.0001*O24) -> 126.6021
B25: 1 | C25: 2 | D25: 3 | E25: 4 | F25: 5 | G25: 6 | H25: 7 | I25: 8 | J25: 9 | K25: 10 | O25: =O24+1 -> 22 | P25: С245 | Q25: 240 | R25: кв.140х6 | S25: 140 | T25: 140 | X25: 32.1 | Y25: 25.2 | Z25: 947.1 | AA25: 135.3 | AC25: 5.43 | AD25: 947.1 | AE25: 135.3 | AF25: 5.43 | AH25: =MAX($D$18*100/$AC25,$D$17*100/$AF25)/200 -> 0.55248619 | AK25: =(($AK$2+Y25*Лист1!$B$7^2*Лист1!$G$8/100)/(AA25/10^6)+$AK$3/(AE25/10^6))/1000/($Q25*IF(Лист1!$J$19="да",1/1.05,1)) -> 0.23998448 | AN25: =(($AK$2+Y25*Лист1!$B$7^2*Лист1!$G$8/100)/(AA25/10^6)+$AK$3/(AE25/10^6))/1000/($Q25*IF(Лист1!$J$19="да",1/1.05,1)) -> 0.23998448 | AQ25: =MAX((5/384*($AQ$2+$Y25/100)*$D$17^4/(2.06*10^8*$Z25/10^8))/($D$17/300)*INDEX(Лист1!$L$34:$L$38,MATCH(Лист1!$B$8,Лист1!$I$34:$I$38,0),1),(5/384*($AQ$3)*$D$17^4/(2.06*10^8*$AD25/10^8))/($D$17/200)) -> 0.32953815 | AT25: =MAX((5/384*($AT$2+$Y25/100)*$D$17^4/(2.06*10^8*$Z25/10^8))/($D$17/300)*INDEX(Лист1!$L$34:$L$38,MATCH(Лист1!$B$8,Лист1!$I$34:$I$38,0),1),(5/384*($AT$3)*$D$17^4/(2.06*10^8*$AD25/10^8))/($D$17/200)) -> 0.16538826 | AV25: =IF(OR(MAX(AH25,AQ25)>1,AK25>Лист1!$B$20,N25="-"),999999999,Y25*Лист1!$B$7+0.0001*O25) -> 151.2022 | AX25: =IF(OR(MAX(AH25,AT25)>1,AN25>Лист1!$B$20,N25="-"),999999999,Y25*Лист1!$B$7+0.0001*O25) -> 151.2022
A26: Подбор | B26: =SMALL($AX$4:$AX$413,B25) -> 54.6011 | C26: =SMALL($AX$4:$AX$413,C25) -> 54.6143 | D26: =SMALL($AX$4:$AX$413,D25) -> 54.6274 | E26: =SMALL($AX$4:$AX$413,E25) -> 54.6347 | F26: =SMALL($AX$4:$AX$413,F25) -> 66.0016 | G26: =SMALL($AX$4:$AX$413,G25) -> 66.0148 | H26: =SMALL($AX$4:$AX$413,H25) -> 72.0012 | I26: =SMALL($AX$4:$AX$413,I25) -> 72.007 | ... K26: =SMALL($AX$4:$AX$413,K25) -> 72.0202 | O26: =O25+1 -> 23 | P26: С245 | Q26: 240 | R26: кв.140х7 | S26: 140 | T26: 140 | X26: 37.2 | Y26: 29.2 | Z26: 1077.1 | AA26: 153.9 | AC26: 5.38 | AD26: 1077.1 | AE26: 153.9 | AF26: 5.38 | AH26: =MAX($D$18*100/$AC26,$D$17*100/$AF26)/200 -> 0.55762082 | AK26: =(($AK$2+Y26*Лист1!$B$7^2*Лист1!$G$8/100)/(AA26/10^6)+$AK$3/(AE26/10^6))/1000/($Q26*IF(Лист1!$J$19="да",1/1.05,1)) -> 0.2158538 | AN26: =(($AK$2+Y26*Лист1!$B$7^2*Лист1!$G$8/100)/(AA26/10^6)+$AK$3/(AE26/10^6))/1000/($Q26*IF(Лист1!$J$19="да",1/1.05,1)) -> 0.2158538 | AQ26: =MAX((5/384*($AQ$2+$Y26/100)*$D$17^4/(2.06*10^8*$Z26/10^8))/($D$17/300)*INDEX(Лист1!$L$34:$L$38,MATCH(Лист1!$B$8,Лист1!$I$34:$I$38,0),1),(5/384*($AQ$3)*$D$17^4/(2.06*10^8*$AD26/10^8))/($D$17/200)) -> 0.30497547 | AT26: =MAX((5/384*($AT$2+$Y26/100)*$D$17^4/(2.06*10^8*$Z26/10^8))/($D$17/300)*INDEX(Лист1!$L$34:$L$38,MATCH(Лист1!$B$8,Лист1!$I$34:$I$38,0),1),(5/384*($AT$3)*$D$17^4/(2.06*10^8*$AD26/10^8))/($D$17/200)) -> 0.14542681 | AV26: =IF(OR(MAX(AH26,AQ26)>1,AK26>Лист1!$B$20,N26="-"),999999999,Y26*Лист1!$B$7+0.0001*O26) -> 175.2023 | AX26: =IF(OR(MAX(AH26,AT26)>1,AN26>Лист1!$B$20,N26="-"),999999999,Y26*Лист1!$B$7+0.0001*O26) -> 175.2023
A27: сечение | B27: =INDEX($R$4:$R$413,MATCH(B26,$AX$4:$AX$413,0),1) -> кв.100х3 | C27: =INDEX($R$4:$R$413,MATCH(C26,$AX$4:$AX$413,0),1) -> кв.100х3 | D27: =INDEX($R$4:$R$413,MATCH(D26,$AX$4:$AX$413,0),1) -> пр.120х80х3 90° | E27: =INDEX($R$4:$R$413,MATCH(E26,$AX$4:$AX$413,0),1) -> пр.120х80х3 90° | F27: =INDEX($R$4:$R$413,MATCH(F26,$AX$4:$AX$413,0),1) -> кв.120х3 | G27: =INDEX($R$4:$R$413,MATCH(G26,$AX$4:$AX$413,0),1) -> кв.120х3 | H27: =INDEX($R$4:$R$413,MATCH(H26,$AX$4:$AX$413,0),1) -> кв.100х4 | I27: =INDEX($R$4:$R$413,MATCH(I26,$AX$4:$AX$413,0),1) -> пр.120х80х4 | ... K27: =INDEX($R$4:$R$413,MATCH(K26,$AX$4:$AX$413,0),1) -> пр.120х80х4 | O27: =O26+1 -> 24 | P27: С245 | Q27: 240 | R27: кв.140х8 | S27: 140 | T27: 140 | X27: 42.3 | Y27: 33.2 | Z27: 1201.7 | AA27: 171.7 | AC27: 5.33 | AD27: 1201.7 | AE27: 171.7 | AF27: 5.33 | AH27: =MAX($D$18*100/$AC27,$D$17*100/$AF27)/200 -> 0.56285178 | AK27: =(($AK$2+Y27*Лист1!$B$7^2*Лист1!$G$8/100)/(AA27/10^6)+$AK$3/(AE27/10^6))/1000/($Q27*IF(Лист1!$J$19="да",1/1.05,1)) -> 0.1978445 | AN27: =(($AK$2+Y27*Лист1!$B$7^2*Лист1!$G$8/100)/(AA27/10^6)+$AK$3/(AE27/10^6))/1000/($Q27*IF(Лист1!$J$19="да",1/1.05,1)) -> 0.1978445 | AQ27: =MAX((5/384*($AQ$2+$Y27/100)*$D$17^4/(2.06*10^8*$Z27/10^8))/($D$17/300)*INDEX(Лист1!$L$34:$L$38,MATCH(Лист1!$B$8,Лист1!$I$34:$I$38,0),1),(5/384*($AQ$3)*$D$17^4/(2.06*10^8*$AD27/10^8))/($D$17/200)) -> 0.28698725 | AT27: =MAX((5/384*($AT$2+$Y27/100)*$D$17^4/(2.06*10^8*$Z27/10^8))/($D$17/300)*INDEX(Лист1!$L$34:$L$38,MATCH(Лист1!$B$8,Лист1!$I$34:$I$38,0),1),(5/384*($AT$3)*$D$17^4/(2.06*10^8*$AD27/10^8))/($D$17/200)) -> 0.14383446 | AV27: =IF(OR(MAX(AH27,AQ27)>1,AK27>Лист1!$B$20,N27="-"),999999999,Y27*Лист1!$B$7+0.0001*O27) -> 199.2024 | AX27: =IF(OR(MAX(AH27,AT27)>1,AN27>Лист1!$B$20,N27="-"),999999999,Y27*Лист1!$B$7+0.0001*O27) -> 199.2024
A28: сталь | B28: =INDEX($P$4:$P$413,MATCH(B26,$AX$4:$AX$413,0),1) -> С245 | C28: =INDEX($P$4:$P$413,MATCH(C26,$AX$4:$AX$413,0),1) -> С345 | D28: =INDEX($P$4:$P$413,MATCH(D26,$AX$4:$AX$413,0),1) -> С245 | E28: =INDEX($P$4:$P$413,MATCH(E26,$AX$4:$AX$413,0),1) -> С345 | F28: =INDEX($P$4:$P$413,MATCH(F26,$AX$4:$AX$413,0),1) -> С245 | G28: =INDEX($P$4:$P$413,MATCH(G26,$AX$4:$AX$413,0),1) -> С345 | H28: =INDEX($P$4:$P$413,MATCH(H26,$AX$4:$AX$413,0),1) -> С245 | I28: =INDEX($P$4:$P$413,MATCH(I26,$AX$4:$AX$413,0),1) -> С245 | ... K28: =INDEX($P$4:$P$413,MATCH(K26,$AX$4:$AX$413,0),1) -> С345 | O28: =O27+1 -> 25 | P28: С245 | Q28: 240 | R28: кв.160х4 | S28: 160 | T28: 160 | X28: 24.7 | Y28: 19.4 | Z28: 989.7 | AA28: 123.7 | AC28: 6.33 | AD28: 989.7 | AE28: 123.7 | AF28: 6.33 | AH28: =MAX($D$18*100/$AC28,$D$17*100/$AF28)/200 -> 0.47393365 | AK28: =(($AK$2+Y28*Лист1!$B$7^2*Лист1!$G$8/100)/(AA28/10^6)+$AK$3/(AE28/10^6))/1000/($Q28*IF(Лист1!$J$19="да",1/1.05,1)) -> 0.25369766 | AN28: =(($AK$2+Y28*Лист1!$B$7^2*Лист1!$G$8/100)/(AA28/10^6)+$AK$3/(AE28/10^6))/1000/($Q28*IF(Лист1!$J$19="да",1/1.05,1)) -> 0.25369766 | AQ28: =MAX((5/384*($AQ$2+$Y28/100)*$D$17^4/(2.06*10^8*$Z28/10^8))/($D$17/300)*INDEX(Лист1!$L$34:$L$38,MATCH(Лист1!$B$8,Лист1!$I$34:$I$38,0),1),(5/384*($AQ$3)*$D$17^4/(2.06*10^8*$AD28/10^8))/($D$17/200)) -> 0.29135042 | AT28: =MAX((5/384*($AT$2+$Y28/100)*$D$17^4/(2.06*10^8*$Z28/10^8))/($D$17/300)*INDEX(Лист1!$L$34:$L$38,MATCH(Лист1!$B$8,Лист1!$I$34:$I$38,0),1),(5/384*($AT$3)*$D$17^4/(2.06*10^8*$AD28/10^8))/($D$17/200)) -> 0.15826939 | AV28: =IF(OR(MAX(AH28,AQ28)>1,AK28>Лист1!$B$20,N28="-"),999999999,Y28*Лист1!$B$7+0.0001*O28) -> 116.4025 | AX28: =IF(OR(MAX(AH28,AT28)>1,AN28>Лист1!$B$20,N28="-"),999999999,Y28*Лист1!$B$7+0.0001*O28) -> 116.4025
O29: =O28+1 -> 26 | P29: С245 | Q29: 240 | R29: кв.160х5 | S29: 160 | T29: 160 | X29: 30.7 | Y29: 24.1 | Z29: 1214.6 | AA29: 151.8 | AC29: 6.29 | AD29: 1214.6 | AE29: 151.8 | AF29: 6.29 | AH29: =MAX($D$18*100/$AC29,$D$17*100/$AF29)/200 -> 0.47694754 | AK29: =(($AK$2+Y29*Лист1!$B$7^2*Лист1!$G$8/100)/(AA29/10^6)+$AK$3/(AE29/10^6))/1000/($Q29*IF(Лист1!$J$19="да",1/1.05,1)) -> 0.21254052 | AN29: =(($AK$2+Y29*Лист1!$B$7^2*Лист1!$G$8/100)/(AA29/10^6)+$AK$3/(AE29/10^6))/1000/($Q29*IF(Лист1!$J$19="да",1/1.05,1)) -> 0.21254052 | AQ29: =MAX((5/384*($AQ$2+$Y29/100)*$D$17^4/(2.06*10^8*$Z29/10^8))/($D$17/300)*INDEX(Лист1!$L$34:$L$38,MATCH(Лист1!$B$8,Лист1!$I$34:$I$38,0),1),(5/384*($AQ$3)*$D$17^4/(2.06*10^8*$AD29/10^8))/($D$17/200)) -> 0.2532522 | AT29: =MAX((5/384*($AT$2+$Y29/100)*$D$17^4/(2.06*10^8*$Z29/10^8))/($D$17/300)*INDEX(Лист1!$L$34:$L$38,MATCH(Лист1!$B$8,Лист1!$I$34:$I$38,0),1),(5/384*($AT$3)*$D$17^4/(2.06*10^8*$AD29/10^8))/($D$17/200)) -> 0.12896363 | AV29: =IF(OR(MAX(AH29,AQ29)>1,AK29>Лист1!$B$20,N29="-"),999999999,Y29*Лист1!$B$7+0.0001*O29) -> 144.6026 | AX29: =IF(OR(MAX(AH29,AT29)>1,AN29>Лист1!$B$20,N29="-"),999999999,Y29*Лист1!$B$7+0.0001*O29) -> 144.6026
O30: =O29+1 -> 27 | P30: С245 | Q30: 240 | R30: кв.160х6 | S30: 160 | T30: 160 | X30: 36.8 | Y30: 28.9 | Z30: 1435.1 | AA30: 179.4 | AC30: 6.24 | AD30: 1435.1 | AE30: 179.4 | AF30: 6.24 | AH30: =MAX($D$18*100/$AC30,$D$17*100/$AF30)/200 -> 0.48076923 | AK30: =(($AK$2+Y30*Лист1!$B$7^2*Лист1!$G$8/100)/(AA30/10^6)+$AK$3/(AE30/10^6))/1000/($Q30*IF(Лист1!$J$19="да",1/1.05,1)) -> 0.1848587 | AN30: =(($AK$2+Y30*Лист1!$B$7^2*Лист1!$G$8/100)/(AA30/10^6)+$AK$3/(AE30/10^6))/1000/($Q30*IF(Лист1!$J$19="да",1/1.05,1)) -> 0.1848587 | AQ30: =MAX((5/384*($AQ$2+$Y30/100)*$D$17^4/(2.06*10^8*$Z30/10^8))/($D$17/300)*INDEX(Лист1!$L$34:$L$38,MATCH(Лист1!$B$8,Лист1!$I$34:$I$38,0),1),(5/384*($AQ$3)*$D$17^4/(2.06*10^8*$AD30/10^8))/($D$17/200)) -> 0.22804008 | AT30: =MAX((5/384*($AT$2+$Y30/100)*$D$17^4/(2.06*10^8*$Z30/10^8))/($D$17/300)*INDEX(Лист1!$L$34:$L$38,MATCH(Лист1!$B$8,Лист1!$I$34:$I$38,0),1),(5/384*($AT$3)*$D$17^4/(2.06*10^8*$AD30/10^8))/($D$17/200)) -> 0.10914864 | AV30: =IF(OR(MAX(AH30,AQ30)>1,AK30>Лист1!$B$20,N30="-"),999999999,Y30*Лист1!$B$7+0.0001*O30) -> 173.4027 | AX30: =IF(OR(MAX(AH30,AT30)>1,AN30>Лист1!$B$20,N30="-"),999999999,Y30*Лист1!$B$7+0.0001*O30) -> 173.4027
N31: - | O31: =O30+1 -> 28 | P31: С245 | Q31: 240 | R31: кв.160х7 | S31: 160 | T31: 160 | X31: 42.8 | Y31: 33.6 | Z31: 1640.8 | AA31: 205.1 | AC31: 6.2 | AD31: 1640.8 | AE31: 205.1 | AF31: 6.2 | AH31: =MAX($D$18*100/$AC31,$D$17*100/$AF31)/200 -> 0.48387097 | AK31: =(($AK$2+Y31*Лист1!$B$7^2*Лист1!$G$8/100)/(AA31/10^6)+$AK$3/(AE31/10^6))/1000/($Q31*IF(Лист1!$J$19="да",1/1.05,1)) -> 0.16599171 | AN31: =(($AK$2+Y31*Лист1!$B$7^2*Лист1!$G$8/100)/(AA31/10^6)+$AK$3/(AE31/10^6))/1000/($Q31*IF(Лист1!$J$19="да",1/1.05,1)) -> 0.16599171 | AQ31: =MAX((5/384*($AQ$2+$Y31/100)*$D$17^4/(2.06*10^8*$Z31/10^8))/($D$17/300)*INDEX(Лист1!$L$34:$L$38,MATCH(Лист1!$B$8,Лист1!$I$34:$I$38,0),1),(5/384*($AQ$3)*$D$17^4/(2.06*10^8*$AD31/10^8))/($D$17/200)) -> 0.21118413 | AT31: =MAX((5/384*($AT$2+$Y31/100)*$D$17^4/(2.06*10^8*$Z31/10^8))/($D$17/300)*INDEX(Лист1!$L$34:$L$38,MATCH(Лист1!$B$8,Лист1!$I$34:$I$38,0),1),(5/384*($AT$3)*$D$17^4/(2.06*10^8*$AD31/10^8))/($D$17/200)) -> 0.10634095 | AV31: =IF(OR(MAX(AH31,AQ31)>1,AK31>Лист1!$B$20,N31="-"),999999999,Y31*Лист1!$B$7+0.0001*O31) -> 999999999 | AX31: =IF(OR(MAX(AH31,AT31)>1,AN31>Лист1!$B$20,N31="-"),999999999,Y31*Лист1!$B$7+0.0001*O31) -> 999999999
O32: =O31+1 -> 29 | P32: С245 | Q32: 240 | R32: кв.160х8 | S32: 160 | T32: 160 | X32: 48.7 | Y32: 38.2 | Z32: 1836.9 | AA32: 229.6 | AC32: 6.15 | AD32: 1836.9 | AE32: 229.6 | AF32: 6.15 | AH32: =MAX($D$18*100/$AC32,$D$17*100/$AF32)/200 -> 0.48780488 | AK32: =(($AK$2+Y32*Лист1!$B$7^2*Лист1!$G$8/100)/(AA32/10^6)+$AK$3/(AE32/10^6))/1000/($Q32*IF(Лист1!$J$19="да",1/1.05,1)) -> 0.15203572 | AN32: =(($AK$2+Y32*Лист1!$B$7^2*Лист1!$G$8/100)/(AA32/10^6)+$AK$3/(AE32/10^6))/1000/($Q32*IF(Лист1!$J$19="да",1/1.05,1)) -> 0.15203572 | AQ32: =MAX((5/384*($AQ$2+$Y32/100)*$D$17^4/(2.06*10^8*$Z32/10^8))/($D$17/300)*INDEX(Лист1!$L$34:$L$38,MATCH(Лист1!$B$8,Лист1!$I$34:$I$38,0),1),(5/384*($AQ$3)*$D$17^4/(2.06*10^8*$AD32/10^8))/($D$17/200)) -> 0.19889593 | AT32: =MAX((5/384*($AT$2+$Y32/100)*$D$17^4/(2.06*10^8*$Z32/10^8))/($D$17/300)*INDEX(Лист1!$L$34:$L$38,MATCH(Лист1!$B$8,Лист1!$I$34:$I$38,0),1),(5/384*($AT$3)*$D$17^4/(2.06*10^8*$AD32/10^8))/($D$17/200)) -> 0.10524538 | AV32: =IF(OR(MAX(AH32,AQ32)>1,AK32>Лист1!$B$20,N32="-"),999999999,Y32*Лист1!$B$7+0.0001*O32) -> 229.2029 | AX32: =IF(OR(MAX(AH32,AT32)>1,AN32>Лист1!$B$20,N32="-"),999999999,Y32*Лист1!$B$7+0.0001*O32) -> 229.2029
O33: =O32+1 -> 30 | P33: С245 | Q33: 240 | R33: кв.180х5 | S33: 180 | T33: 180 | X33: 34.6 | Y33: 27.2 | Z33: 1749.1 | AA33: 194.3 | AC33: 7.11 | AD33: 1749.1 | AE33: 194.3 | AF33: 7.11 | AH33: =MAX($D$18*100/$AC33,$D$17*100/$AF33)/200 -> 0.42194093 | AK33: =(($AK$2+Y33*Лист1!$B$7^2*Лист1!$G$8/100)/(AA33/10^6)+$AK$3/(AE33/10^6))/1000/($Q33*IF(Лист1!$J$19="да",1/1.05,1)) -> 0.1690422 | AN33: =(($AK$2+Y33*Лист1!$B$7^2*Лист1!$G$8/100)/(AA33/10^6)+$AK$3/(AE33/10^6))/1000/($Q33*IF(Лист1!$J$19="да",1/1.05,1)) -> 0.1690422 | AQ33: =MAX((5/384*($AQ$2+$Y33/100)*$D$17^4/(2.06*10^8*$Z33/10^8))/($D$17/300)*INDEX(Лист1!$L$34:$L$38,MATCH(Лист1!$B$8,Лист1!$I$34:$I$38,0),1),(5/384*($AQ$3)*$D$17^4/(2.06*10^8*$AD33/10^8))/($D$17/200)) -> 0.18312122 | AT33: =MAX((5/384*($AT$2+$Y33/100)*$D$17^4/(2.06*10^8*$Z33/10^8))/($D$17/300)*INDEX(Лист1!$L$34:$L$38,MATCH(Лист1!$B$8,Лист1!$I$34:$I$38,0),1),(5/384*($AT$3)*$D$17^4/(2.06*10^8*$AD33/10^8))/($D$17/200)) -> 0.089554182 | AV33: =IF(OR(MAX(AH33,AQ33)>1,AK33>Лист1!$B$20,N33="-"),999999999,Y33*Лист1!$B$7+0.0001*O33) -> 163.203 | AX33: =IF(OR(MAX(AH33,AT33)>1,AN33>Лист1!$B$20,N33="-"),999999999,Y33*Лист1!$B$7+0.0001*O33) -> 163.203
O34: =O33+1 -> 31 | P34: С245 | Q34: 240 | R34: кв.180х6 | S34: 180 | T34: 180 | X34: 41.4 | Y34: 32.5 | Z34: 2063.5 | AA34: 229.3 | AC34: 7.06 | AD34: 2063.5 | AE34: 229.3 | AF34: 7.06 | AH34: =MAX($D$18*100/$AC34,$D$17*100/$AF34)/200 -> 0.42492918 | AK34: =(($AK$2+Y34*Лист1!$B$7^2*Лист1!$G$8/100)/(AA34/10^6)+$AK$3/(AE34/10^6))/1000/($Q34*IF(Лист1!$J$19="да",1/1.05,1)) -> 0.1475737 | AN34: =(($AK$2+Y34*Лист1!$B$7^2*Лист1!$G$8/100)/(AA34/10^6)+$AK$3/(AE34/10^6))/1000/($Q34*IF(Лист1!$J$19="да",1/1.05,1)) -> 0.1475737 | AQ34: =MAX((5/384*($AQ$2+$Y34/100)*$D$17^4/(2.06*10^8*$Z34/10^8))/($D$17/300)*INDEX(Лист1!$L$34:$L$38,MATCH(Лист1!$B$8,Лист1!$I$34:$I$38,0),1),(5/384*($AQ$3)*$D$17^4/(2.06*10^8*$AD34/10^8))/($D$17/200)) -> 0.16574047 | AT34: =MAX((5/384*($AT$2+$Y34/100)*$D$17^4/(2.06*10^8*$Z34/10^8))/($D$17/300)*INDEX(Лист1!$L$34:$L$38,MATCH(Лист1!$B$8,Лист1!$I$34:$I$38,0),1),(5/384*($AT$3)*$D$17^4/(2.06*10^8*$AD34/10^8))/($D$17/200)) -> 0.082374006 | AV34: =IF(OR(MAX(AH34,AQ34)>1,AK34>Лист1!$B$20,N34="-"),999999999,Y34*Лист1!$B$7+0.0001*O34) -> 195.0031 | AX34: =IF(OR(MAX(AH34,AT34)>1,AN34>Лист1!$B$20,N34="-"),999999999,Y34*Лист1!$B$7+0.0001*O34) -> 195.0031
O35: =O34+1 -> 32 | P35: С245 | Q35: 240 | R35: кв.180х7 | S35: 180 | T35: 180 | X35: 48.2 | Y35: 37.8 | Z35: 2372.1 | AA35: 263.6 | AC35: 7.01 | AD35: 2372.1 | AE35: 263.6 | AF35: 7.01 | AH35: =MAX($D$18*100/$AC35,$D$17*100/$AF35)/200 -> 0.42796006 | AK35: =(($AK$2+Y35*Лист1!$B$7^2*Лист1!$G$8/100)/(AA35/10^6)+$AK$3/(AE35/10^6))/1000/($Q35*IF(Лист1!$J$19="да",1/1.05,1)) -> 0.13214112 | AN35: =(($AK$2+Y35*Лист1!$B$7^2*Лист1!$G$8/100)/(AA35/10^6)+$AK$3/(AE35/10^6))/1000/($Q35*IF(Лист1!$J$19="да",1/1.05,1)) -> 0.13214112 | AQ35: =MAX((5/384*($AQ$2+$Y35/100)*$D$17^4/(2.06*10^8*$Z35/10^8))/($D$17/300)*INDEX(Лист1!$L$34:$L$38,MATCH(Лист1!$B$8,Лист1!$I$34:$I$38,0),1),(5/384*($AQ$3)*$D$17^4/(2.06*10^8*$AD35/10^8))/($D$17/200)) -> 0.15332979 | AT35: =MAX((5/384*($AT$2+$Y35/100)*$D$17^4/(2.06*10^8*$Z35/10^8))/($D$17/300)*INDEX(Лист1!$L$34:$L$38,MATCH(Лист1!$B$8,Лист1!$I$34:$I$38,0),1),(5/384*($AT$3)*$D$17^4/(2.06*10^8*$AD35/10^8))/($D$17/200)) -> 0.080808943 | AV35: =IF(OR(MAX(AH35,AQ35)>1,AK35>Лист1!$B$20,N35="-"),999999999,Y35*Лист1!$B$7+0.0001*O35) -> 226.8032 | AX35: =IF(OR(MAX(AH35,AT35)>1,AN35>Лист1!$B$20,N35="-"),999999999,Y35*Лист1!$B$7+0.0001*O35) -> 226.8032
O36: =O35+1 -> 33 | P36: С245 | Q36: 240 | R36: кв.180х8 | S36: 180 | T36: 180 | X36: 54.8 | Y36: 43 | Z36: 2663.3 | AA36: 295.9 | AC36: 6.97 | AD36: 2663.3 | AE36: 295.9 | AF36: 6.97 | AH36: =MAX($D$18*100/$AC36,$D$17*100/$AF36)/200 -> 0.43041607 | AK36: =(($AK$2+Y36*Лист1!$B$7^2*Лист1!$G$8/100)/(AA36/10^6)+$AK$3/(AE36/10^6))/1000/($Q36*IF(Лист1!$J$19="да",1/1.05,1)) -> 0.12101183 | AN36: =(($AK$2+Y36*Лист1!$B$7^2*Лист1!$G$8/100)/(AA36/10^6)+$AK$3/(AE36/10^6))/1000/($Q36*IF(Лист1!$J$19="да",1/1.05,1)) -> 0.12101183 | AQ36: =MAX((5/384*($AQ$2+$Y36/100)*$D$17^4/(2.06*10^8*$Z36/10^8))/($D$17/300)*INDEX(Лист1!$L$34:$L$38,MATCH(Лист1!$B$8,Лист1!$I$34:$I$38,0),1),(5/384*($AQ$3)*$D$17^4/(2.06*10^8*$AD36/10^8))/($D$17/200)) -> 0.14456206 | AT36: =MAX((5/384*($AT$2+$Y36/100)*$D$17^4/(2.06*10^8*$Z36/10^8))/($D$17/300)*INDEX(Лист1!$L$34:$L$38,MATCH(Лист1!$B$8,Лист1!$I$34:$I$38,0),1),(5/384*($AT$3)*$D$17^4/(2.06*10^8*$AD36/10^8))/($D$17/200)) -> 0.079970502 | AV36: =IF(OR(MAX(AH36,AQ36)>1,AK36>Лист1!$B$20,N36="-"),999999999,Y36*Лист1!$B$7+0.0001*O36) -> 258.0033 | AX36: =IF(OR(MAX(AH36,AT36)>1,AN36>Лист1!$B$20,N36="-"),999999999,Y36*Лист1!$B$7+0.0001*O36) -> 258.0033
O37: =O36+1 -> 34 | P37: С245 | Q37: 240 | R37: кв.180х9 | S37: 180 | T37: 180 | X37: 61.5 | Y37: 48.3 | Z37: 2976.5 | AA37: 326.2 | AC37: 6.91 | AD37: 2976.5 | AE37: 326.2 | AF37: 6.91 | AH37: =MAX($D$18*100/$AC37,$D$17*100/$AF37)/200 -> 0.4341534 | AK37: =(($AK$2+Y37*Лист1!$B$7^2*Лист1!$G$8/100)/(AA37/10^6)+$AK$3/(AE37/10^6))/1000/($Q37*IF(Лист1!$J$19="да",1/1.05,1)) -> 0.11281775 | AN37: =(($AK$2+Y37*Лист1!$B$7^2*Лист1!$G$8/100)/(AA37/10^6)+$AK$3/(AE37/10^6))/1000/($Q37*IF(Лист1!$J$19="да",1/1.05,1)) -> 0.11281775 | AQ37: =MAX((5/384*($AQ$2+$Y37/100)*$D$17^4/(2.06*10^8*$Z37/10^8))/($D$17/300)*INDEX(Лист1!$L$34:$L$38,MATCH(Лист1!$B$8,Лист1!$I$34:$I$38,0),1),(5/384*($AQ$3)*$D$17^4/(2.06*10^8*$AD37/10^8))/($D$17/200)) -> 0.1366438 | AT37: =MAX((5/384*($AT$2+$Y37/100)*$D$17^4/(2.06*10^8*$Z37/10^8))/($D$17/300)*INDEX(Лист1!$L$34:$L$38,MATCH(Лист1!$B$8,Лист1!$I$34:$I$38,0),1),(5/384*($AT$3)*$D$17^4/(2.06*10^8*$AD37/10^8))/($D$17/200)) -> 0.078848839 | AV37: =IF(OR(MAX(AH37,AQ37)>1,AK37>Лист1!$B$20,N37="-"),999999999,Y37*Лист1!$B$7+0.0001*O37) -> 289.8034 | AX37: =IF(OR(MAX(AH37,AT37)>1,AN37>Лист1!$B$20,N37="-"),999999999,Y37*Лист1!$B$7+0.0001*O37) -> 289.8034
O38: =O37+1 -> 35 | P38: С245 | Q38: 240 | R38: кв.180х10 | S38: 180 | T38: 180 | X38: 68.2 | Y38: 53.5 | Z38: 3300.7 | AA38: 353.5 | AC38: 6.86 | AD38: 3300.7 | AE38: 353.5 | AF38: 6.86 | AH38: =MAX($D$18*100/$AC38,$D$17*100/$AF38)/200 -> 0.43731778 | AK38: =(($AK$2+Y38*Лист1!$B$7^2*Лист1!$G$8/100)/(AA38/10^6)+$AK$3/(AE38/10^6))/1000/($Q38*IF(Лист1!$J$19="да",1/1.05,1)) -> 0.10686323 | AN38: =(($AK$2+Y38*Лист1!$B$7^2*Лист1!$G$8/100)/(AA38/10^6)+$AK$3/(AE38/10^6))/1000/($Q38*IF(Лист1!$J$19="да",1/1.05,1)) -> 0.10686323 | AQ38: =MAX((5/384*($AQ$2+$Y38/100)*$D$17^4/(2.06*10^8*$Z38/10^8))/($D$17/300)*INDEX(Лист1!$L$34:$L$38,MATCH(Лист1!$B$8,Лист1!$I$34:$I$38,0),1),(5/384*($AQ$3)*$D$17^4/(2.06*10^8*$AD38/10^8))/($D$17/200)) -> 0.12967516 | AT38: =MAX((5/384*($AT$2+$Y38/100)*$D$17^4/(2.06*10^8*$Z38/10^8))/($D$17/300)*INDEX(Лист1!$L$34:$L$38,MATCH(Лист1!$B$8,Лист1!$I$34:$I$38,0),1),(5/384*($AT$3)*$D$17^4/(2.06*10^8*$AD38/10^8))/($D$17/200)) -> 0.077556916 | AV38: =IF(OR(MAX(AH38,AQ38)>1,AK38>Лист1!$B$20,N38="-"),999999999,Y38*Лист1!$B$7+0.0001*O38) -> 321.0035 | AX38: =IF(OR(MAX(AH38,AT38)>1,AN38>Лист1!$B$20,N38="-"),999999999,Y38*Лист1!$B$7+0.0001*O38) -> 321.0035
N39: - | O39: =O38+1 -> 36 | P39: С245 | Q39: 240 | R39: кв.200х5 | S39: 200 | T39: 200 | X39: 38.4 | Y39: 30.1 | Z39: 2410 | AA39: 241 | AC39: 7.93 | AD39: 2410 | AE39: 241 | AF39: 7.93 | AH39: =MAX($D$18*100/$AC39,$D$17*100/$AF39)/200 -> 0.37831021 | AK39: =(($AK$2+Y39*Лист1!$B$7^2*Лист1!$G$8/100)/(AA39/10^6)+$AK$3/(AE39/10^6))/1000/($Q39*IF(Лист1!$J$19="да",1/1.05,1)) -> 0.13854212 | AN39: =(($AK$2+Y39*Лист1!$B$7^2*Лист1!$G$8/100)/(AA39/10^6)+$AK$3/(AE39/10^6))/1000/($Q39*IF(Лист1!$J$19="да",1/1.05,1)) -> 0.13854212 | AQ39: =MAX((5/384*($AQ$2+$Y39/100)*$D$17^4/(2.06*10^8*$Z39/10^8))/($D$17/300)*INDEX(Лист1!$L$34:$L$38,MATCH(Лист1!$B$8,Лист1!$I$34:$I$38,0),1),(5/384*($AQ$3)*$D$17^4/(2.06*10^8*$AD39/10^8))/($D$17/200)) -> 0.1378321 | AT39: =MAX((5/384*($AT$2+$Y39/100)*$D$17^4/(2.06*10^8*$Z39/10^8))/($D$17/300)*INDEX(Лист1!$L$34:$L$38,MATCH(Лист1!$B$8,Лист1!$I$34:$I$38,0),1),(5/384*($AT$3)*$D$17^4/(2.06*10^8*$AD39/10^8))/($D$17/200)) -> 0.066451728 | AV39: =IF(OR(MAX(AH39,AQ39)>1,AK39>Лист1!$B$20,N39="-"),999999999,Y39*Лист1!$B$7+0.0001*O39) -> 999999999 | AX39: =IF(OR(MAX(AH39,AT39)>1,AN39>Лист1!$B$20,N39="-"),999999999,Y39*Лист1!$B$7+0.0001*O39) -> 999999999
O40: =O39+1 -> 37 | P40: С245 | Q40: 240 | R40: кв.200х6 | S40: 200 | T40: 200 | X40: 45.6 | Y40: 35.8 | Z40: 2832 | AA40: 283 | AC40: 7.88 | AD40: 2832 | AE40: 283 | AF40: 7.88 | AH40: =MAX($D$18*100/$AC40,$D$17*100/$AF40)/200 -> 0.38071066 | AK40: =(($AK$2+Y40*Лист1!$B$7^2*Лист1!$G$8/100)/(AA40/10^6)+$AK$3/(AE40/10^6))/1000/($Q40*IF(Лист1!$J$19="да",1/1.05,1)) -> 0.1217576 | AN40: =(($AK$2+Y40*Лист1!$B$7^2*Лист1!$G$8/100)/(AA40/10^6)+$AK$3/(AE40/10^6))/1000/($Q40*IF(Лист1!$J$19="да",1/1.05,1)) -> 0.1217576 | AQ40: =MAX((5/384*($AQ$2+$Y40/100)*$D$17^4/(2.06*10^8*$Z40/10^8))/($D$17/300)*INDEX(Лист1!$L$34:$L$38,MATCH(Лист1!$B$8,Лист1!$I$34:$I$38,0),1),(5/384*($AQ$3)*$D$17^4/(2.06*10^8*$AD40/10^8))/($D$17/200)) -> 0.12553737 | AT40: =MAX((5/384*($AT$2+$Y40/100)*$D$17^4/(2.06*10^8*$Z40/10^8))/($D$17/300)*INDEX(Лист1!$L$34:$L$38,MATCH(Лист1!$B$8,Лист1!$I$34:$I$38,0),1),(5/384*($AT$3)*$D$17^4/(2.06*10^8*$AD40/10^8))/($D$17/200)) -> 0.064793484 | AV40: =IF(OR(MAX(AH40,AQ40)>1,AK40>Лист1!$B$20,N40="-"),999999999,Y40*Лист1!$B$7+0.0001*O40) -> 214.8037 | AX40: =IF(OR(MAX(AH40,AT40)>1,AN40>Лист1!$B$20,N40="-"),999999999,Y40*Лист1!$B$7+0.0001*O40) -> 214.8037
...

Sheet Лист2
A1: Предисловие
A3: Приложение Д. Коэффициенты для расчета на устойчивость центрально и внецентренно сжатых элементов
A5: Условная гибкость | B5: Значение
B6: при приведенном относительном эксцентриситете
B8: 0.1 | C8: 0.25 | D8: 0.5 | E8: 0.75 | F8: 1 | G8: 1.25 | H8: 1.5 | I8: 1.75 | J8: 2 | K8: 2.5 | L8: 3 | M8: 3.5 | N8: 4 | O8: 4.5 | P8: 5 | Q8: 5.5 | R8: 6 | S8: 6.5 | T8: 7 | U8: 7.5 | V8: 8 | W8: 8.5 | X8: 9 | Y8: 9.5 | Z8: 10 | AA8: 10.5 | AB8: 11 | AC8: 11.5 | AD8: 12 | AE8: 12.5 | AF8: 13 | AG8: 13.5 | AH8: 14 | AI8: 14.5 | AJ8: 15 | AK8: 15.5 | AL8: 16 | AM8: 16.5 | AN8: 17 | AO8: 17.5 | AP8: 18 | AQ8: 18.5 | AR8: 19 | AS8: 19.5 | AT8: 20
A9: 0.5 | B9: 967 | C9: 922 | D9: 850 | E9: 782 | F9: 722 | G9: 669 | H9: 620 | I9: 577 | J9: 538 | K9: 469 | L9: 417 | M9: 370 | N9: 337 | O9: 307 | P9: 280 | Q9: 260 | R9: 237 | S9: 222 | T9: 210 | U9: 196.5 | V9: 183 | W9: 173.5 | X9: 164 | Y9: 157 | Z9: 150 | AA9: 143.75 | AB9: 137.5 | AC9: 131.25 | AD9: 125 | AE9: 120.25 | AF9: 115.5 | AG9: 110.75 | AH9: 106 | AI9: 103.33333 | AJ9: 100.66667 | AK9: 98 | AL9: 95.333333 | AM9: 92.666667 | AN9: 90 | AO9: 87.833333 | AP9: 85.666667 | AQ9: 83.5 | AR9: 81.333333 | AS9: 79.166667 | AT9: 77
A10: 1 | B10: 925 | C10: 854 | D10: 778 | E10: 711 | F10: 653 | G10: 600 | H10: 563 | I10: 520 | J10: 484 | K10: 427 | L10: 382 | M10: 341 | N10: 307 | O10: 283 | P10: 259 | Q10: 240 | R10: 225 | S10: 209 | T10: 196 | U10: 185.5 | V10: 175 | W10: 166 | X10: 157 | Y10: 149.5 | Z10: 142 | AA10: 136.75 | AB10: 131.5 | AC10: 126.25 | AD10: 121 | AE10: 116.5 | AF10: 112 | AG10: 107.5 | AH10: 103 | AI10: 100.16667 | AJ10: 97.333333 | AK10: 94.5 | AL10: 91.666667 | AM10: 88.833333 | AN10: 86 | AO10: 84 | AP10: 82 | AQ10: 80 | AR10: 78 | AS10: 76 | AT10: 74
A11: 1.5 | B11: 875 | C11: 804 | D11: 716 | E11: 647 | F11: 593 | G11: 548 | H11: 507 | I11: 470 | J11: 439 | K11: 388 | L11: 347 | M11: 312 | N11: 283 | O11: 262 | P11: 240 | Q11: 223 | R11: 207 | S11: 195 | T11: 182 | U11: 172.5 | V11: 163 | W11: 155.5 | X11: 148 | Y11: 141 | Z11: 134 | AA11: 129 | AB11: 124 | AC11: 119 | AD11: 114 | AE11: 110.25 | AF11: 106.5 | AG11: 102.75 | AH11: 99 | AI11: 96.166667 | AJ11: 93.333333 | AK11: 90.5 | AL11: 87.666667 | AM11: 84.833333 | AN11: 82 | AO11: 80 | AP11: 78 | AQ11: 76 | AR11: 74 | AS11: 72 | AT11: 70
A12: 2 | B12: 813 | C12: 742 | D12: 653 | E12: 587 | F12: 536 | G12: 496 | H12: 457 | I12: 425 | J12: 397 | K12: 352 | L12: 315 | M12: 286 | N12: 260 | O12: 240 | P12: 222 | Q12: 206 | R12: 193 | S12: 182 | T12: 170 | U12: 161.5 | V12: 153 | W12: 145.5 | X12: 138 | Y12: 131.5 | Z12: 125 | AA12: 120.5 | AB12: 116 | AC12: 111.5 | AD12: 107 | AE12: 103.75 | AF12: 100.5 | AG12: 97.25 | AH12: 94 | AI12: 91.5 | AJ12: 89 | AK12: 86.5 | AL12: 84 | AM12: 81.5 | AN12: 79 | AO12: 77 | AP12: 75 | AQ12: 73 | AR12: 71 | AS12: 69 | AT12: 67
A13: 2.5 | B13: 742 | C13: 672 | D13: 587 | E13: 526 | F13: 480 | G13: 442 | H13: 410 | I13: 383 | J13: 357 | K13: 317 | L13: 287 | M13: 262 | N13: 238 | O13: 220 | P13: 204 | Q13: 190 | R13: 178 | S13: 168 | T13: 158 | U13: 151 | V13: 144 | W13: 137 | X13: 130 | Y13: 124 | Z13: 118 | AA13: 113.75 | AB13: 109.5 | AC13: 105.25 | AD13: 101 | AE13: 98.25 | AF13: 95.5 | AG13: 92.75 | AH13: 90 | AI13: 87.666667 | AJ13: 85.333333 | AK13: 83 | AL13: 80.666667 | AM13: 78.333333 | AN13: 76 | AO13: 74.166667 | AP13: 72.333333 | AQ13: 70.5 | AR13: 68.666667 | AS13: 66.833333 | AT13: 65
A14: 3 | B14: 667 | C14: 597 | D14: 520 | E14: 465 | F14: 425 | G14: 395 | H14: 365 | I14: 342 | J14: 320 | K14: 287 | L14: 260 | M14: 238 | N14: 217 | O14: 202 | P14: 187 | Q14: 175 | R14: 166 | S14: 156 | T14: 147 | U14: 141 | V14: 135 | W14: 129 | X14: 123 | Y14: 117.5 | Z14: 112 | AA14: 108.25 | AB14: 104.5 | AC14: 100.75 | AD14: 97 | AE14: 94.25 | AF14: 91.5 | AG14: 88.75 | AH14: 86 | AI14: 83.833333 | AJ14: 81.666667 | AK14: 79.5 | AL14: 77.333333 | AM14: 75.166667 | AN14: 73 | AO14: 71.333333 | AP14: 69.666667 | AQ14: 68 | AR14: 66.333333 | AS14: 64.666667 | AT14: 63
A15: 3.5 | B15: 587 | C15: 522 | D15: 455 | E15: 408 | F15: 375 | G15: 350 | H15: 325 | I15: 303 | J15: 287 | K15: 258 | L15: 233 | M15: 216 | N15: 198 | O15: 183 | P15: 172 | Q15: 162 | R15: 153 | S15: 145 | T15: 137 | U15: 131 | V15: 125 | W15: 120 | X15: 115 | Y15: 110.5 | Z15: 106 | AA15: 102.5 | AB15: 99 | AC15: 95.5 | AD15: 92 | AE15: 89.5 | AF15: 87 | AG15: 84.5 | AH15: 82 | AI15: 79.833333 | AJ15: 77.666667 | AK15: 75.5 | AL15: 73.333333 | AM15: 71.166667 | AN15: 69 | AO15: 67.5 | AP15: 66 | AQ15: 64.5 | AR15: 63 | AS15: 61.5 | AT15: 60
A16: 4 | B16: 505 | C16: 447 | D16: 394 | E16: 356 | F16: 330 | G16: 309 | H16: 289 | I16: 270 | J16: 256 | K16: 232 | L16: 212 | M16: 197 | N16: 181 | O16: 168 | P16: 158 | Q16: 149 | R16: 140 | S16: 135 | T16: 127 | U16: 122.5 | V16: 118 | W16: 113 | X16: 108 | Y16: 103 | Z16: 98 | AA16: 95.5 | AB16: 93 | AC16: 90.5 | AD16: 88 | AE16: 85.5 | AF16: 83 | AG16: 80.5 | AH16: 78 | AI16: 76 | AJ16: 74 | AK16: 72 | AL16: 70 | AM16: 68 | AN16: 66 | AO16: 64.5 | AP16: 63 | AQ16: 61.5 | AR16: 60 | AS16: 58.5 | AT16: 57
A17: 4.5 | B17: 418 | C17: 382 | D17: 342 | E17: 310 | F17: 288 | G17: 272 | H17: 257 | I17: 242 | J17: 229 | K17: 208 | L17: 192 | M17: 178 | N17: 165 | O17: 155 | P17: 146 | Q17: 137 | R17: 130 | S17: 125 | T17: 118 | U17: 114 | V17: 110 | W17: 105.5 | X17: 101 | Y17: 97 | Z17: 93 | AA17: 90.5 | AB17: 88 | AC17: 85.5 | AD17: 83 | AE17: 81 | AF17: 79 | AG17: 77 | AH17: 75 | AI17: 73.166667 | AJ17: 71.333333 | AK17: 69.5 | AL17: 67.666667 | AM17: 65.833333 | AN17: 64 | AO17: 62.5 | AP17: 61 | AQ17: 59.5 | AR17: 58 | AS17: 56.5 | AT17: 55
A18: 5 | B18: 354 | C18: 326 | D18: 295 | E18: 273 | F18: 253 | G18: 239 | H18: 225 | I18: 215 | J18: 205 | K18: 188 | L18: 175 | M18: 162 | N18: 150 | O18: 143 | P18: 135 | Q18: 126 | R18: 120 | S18: 117 | T18: 111 | U18: 107 | V18: 103 | W18: 99 | X18: 95 | Y18: 91.5 | Z18: 88 | AA18: 85.75 | AB18: 83.5 | AC18: 81.25 | AD18: 79 | AE18: 77.25 | AF18: 75.5 | AG18: 73.75 | AH18: 72 | AI18: 70.333333 | AJ18: 68.666667 | AK18: 67 | AL18: 65.333333 | AM18: 63.666667 | AN18: 62 | AO18: 60.5 | AP18: 59 | AQ18: 57.5 | AR18: 56 | AS18: 54.5 | AT18: 53
A19: 5.5 | B19: 302 | C19: 280 | D19: 256 | E19: 240 | F19: 224 | G19: 212 | H19: 200 | I19: 192 | J19: 184 | K19: 170 | L19: 158 | M19: 148 | N19: 138 | O19: 132 | P19: 124 | Q19: 117 | R19: 112 | S19: 108 | T19: 104 | U19: 99.5 | V19: 95 | W19: 92 | X19: 89 | Y19: 86.5 | Z19: 84 | AA19: 81.75 | AB19: 79.5 | AC19: 77.25 | AD19: 75 | AE19: 73.5 | AF19: 72 | AG19: 70.5 | AH19: 69 | AI19: 67.5 | AJ19: 66 | AK19: 64.5 | AL19: 63 | AM19: 61.5 | AN19: 60 | AO19: 58.5 | AP19: 57 | AQ19: 55.5 | AR19: 54 | AS19: 52.5 | AT19: 51
A20: 6 | B20: 258 | C20: 244 | D20: 223 | E20: 210 | F20: 198 | G20: 190 | H20: 178 | I20: 172 | J20: 166 | K20: 153 | L20: 145 | M20: 137 | N20: 128 | O20: 120 | P20: 115 | Q20: 109 | R20: 104 | S20: 100 | T20: ж | U20: ж | V20: ж | W20: ж | X20: ж | Y20: ж | Z20: ж | AA20: ж | AB20: ж | AC20: ж | AD20: ж | AE20: ж | AF20: ж | AG20: ж | AH20: ж | AI20: ж | AJ20: ж | AK20: ж | AL20: ж | AM20: ж | AN20: ж | AO20: ж | AP20: ж | AQ20: ж | AR20: ж | AS20: ж | AT20: ж
A21: 6.5 | B21: 223 | C21: 213 | D21: 196 | E21: 185 | F21: 176 | G21: 170 | H21: 160 | I21: 155 | J21: 149 | K21: 140 | L21: 132 | M21: 125 | N21: 117 | O21: 112 | P21: 106 | Q21: 101 | R21: 97 | S21: 94 | T21: ж | U21: ж | V21: ж | W21: ж | X21: ж | Y21: ж | Z21: ж | AA21: ж | AB21: ж | AC21: ж | AD21: ж | AE21: ж | AF21: ж | AG21: ж | AH21: ж | AI21: ж | AJ21: ж | AK21: ж | AL21: ж | AM21: ж | AN21: ж | AO21: ж | AP21: ж | AQ21: ж | AR21: ж | AS21: ж | AT21: ж
A22: 7 | B22: 194 | C22: 186 | D22: 173 | E22: 163 | F22: 157 | G22: 152 | H22: 145 | I22: 141 | J22: 136 | K22: 127 | L22: 121 | M22: 115 | N22: 108 | O22: 102 | P22: 98 | Q22: 94 | R22: 91 | S22: 87 | T22: ж | U22: ж | V22: ж | W22: ж | X22: ж | Y22: ж | Z22: ж | AA22: ж | AB22: ж | AC22: ж | AD22: ж | AE22: ж | AF22: ж | AG22: ж | AH22: ж | AI22: ж | AJ22: ж | AK22: ж | AL22: ж | AM22: ж | AN22: ж | AO22: ж | AP22: ж | AQ22: ж | AR22: ж | AS22: ж | AT22: ж
